
  <?xml version="1.0" ?>
  <robot name="xela_palm_generated">
  <link name="leap_hand_xela_back_cover">
    <inertial>
      <origin xyz="-0.000780549 -0.00686016 0.0718797" rpy="0 0 0"/>
      <mass value="0.237"/>
      <inertia ixx="0.00330843" ixy="6.79303e-05" ixz="-0.000176923" iyy="0.00420899" iyz="0.000182026" izz="0.00177685"/>
    </inertial>
    <!-- Part leap_hand_xela_motorholder -->
    <visual>
      <origin xyz="0.0180627 0.023 0.0834096" rpy="-3.14159 1.5708 0"/>
      <geometry>
        <mesh filename="package://assets/leap_hand_xela_motorholder.stl"/>
      </geometry>
      <material name="leap_hand_xela_motorholder_material">
        <color rgba="0.792157 0.819608 0.933333 1"/>
      </material>
    </visual>
    <collision>
      <origin xyz="0.0180627 0.023 0.0834096" rpy="-3.14159 1.5708 0"/>
      <geometry>
        <mesh filename="package://assets/leap_hand_xela_motorholder.stl"/>
      </geometry>
    </collision>
    <!-- Part uspa46 -->
    <visual>
      <origin xyz="-0.005515 -0.027 0.0631" rpy="-0 -0 -3.14159"/>
      <geometry>
        <mesh filename="package://assets/uspa46.stl"/>
      </geometry>
      <material name="uspa46_material">
        <color rgba="0.792157 0.819608 0.933333 1"/>
      </material>
    </visual>
    <collision>
      <origin xyz="-0.005515 -0.027 0.0631" rpy="-0 -0 -3.14159"/>
      <geometry>
        <mesh filename="package://assets/uspa46.stl"/>
      </geometry>
    </collision>
    <!-- Part thp0_unified -->
    <visual>
      <origin xyz="0.0235627 -0.013 0.0845" rpy="-0 -0 1.5708"/>
      <geometry>
        <mesh filename="package://assets/thp0_unified.stl"/>
      </geometry>
      <material name="thp0_unified_material">
        <color rgba="0.498039 0.498039 0.498039 1"/>
      </material>
    </visual>
    <collision>
      <origin xyz="0.0235627 -0.013 0.0845" rpy="-0 -0 1.5708"/>
      <geometry>
        <mesh filename="package://assets/thp0_unified.stl"/>
      </geometry>
    </collision>
    <!-- Part p5_unified -->
    <visual>
      <origin xyz="-0.03767 -0.009 0.1306" rpy="1.5708 -1.5708 0"/>
      <geometry>
        <mesh filename="package://assets/p5_unified.stl"/>
      </geometry>
      <material name="p5_unified_material">
        <color rgba="0.980392 0.713725 0.00392157 1"/>
      </material>
    </visual>
    <collision>
      <origin xyz="-0.03767 -0.009 0.1306" rpy="1.5708 -1.5708 0"/>
      <geometry>
        <mesh filename="package://assets/p5_unified.stl"/>
      </geometry>
    </collision>
    <!-- Part top_palm -->
    <visual>
      <origin xyz="0.00785 -0.023 0.123706" rpy="3.14159 0 3.14159"/>
      <geometry>
        <mesh filename="package://assets/top_palm.stl"/>
      </geometry>
      <material name="top_palm_material">
        <color rgba="0.792157 0.819608 0.933333 1"/>
      </material>
    </visual>
    <collision>
      <origin xyz="0.00785 -0.023 0.123706" rpy="3.14159 0 3.14159"/>
      <geometry>
        <mesh filename="package://assets/top_palm.stl"/>
      </geometry>
    </collision>
    <!-- Part p5_unified_2 -->
    <visual>
      <origin xyz="0.00778 -0.009 0.1306" rpy="1.5708 -1.5708 0"/>
      <geometry>
        <mesh filename="package://assets/p5_unified.stl"/>
      </geometry>
      <material name="p5_unified_2_material">
        <color rgba="0.980392 0.713725 0.00392157 1"/>
      </material>
    </visual>
    <collision>
      <origin xyz="0.00778 -0.009 0.1306" rpy="1.5708 -1.5708 0"/>
      <geometry>
        <mesh filename="package://assets/p5_unified.stl"/>
      </geometry>
    </collision>
    <!-- Part uspa46_2 -->
    <visual>
      <origin xyz="-0.005515 -0.027 0.0962" rpy="-0 -0 -3.14159"/>
      <geometry>
        <mesh filename="package://assets/uspa46.stl"/>
      </geometry>
      <material name="uspa46_2_material">
        <color rgba="0.792157 0.819608 0.933333 1"/>
      </material>
    </visual>
    <collision>
      <origin xyz="-0.005515 -0.027 0.0962" rpy="-0 -0 -3.14159"/>
      <geometry>
        <mesh filename="package://assets/uspa46.stl"/>
      </geometry>
    </collision>
    <!-- Part p5_unified_3 -->
    <visual>
      <origin xyz="0.05323 -0.009 0.1306" rpy="1.5708 -1.5708 0"/>
      <geometry>
        <mesh filename="package://assets/p5_unified.stl"/>
      </geometry>
      <material name="p5_unified_3_material">
        <color rgba="0.980392 0.713725 0.00392157 1"/>
      </material>
    </visual>
    <collision>
      <origin xyz="0.05323 -0.009 0.1306" rpy="1.5708 -1.5708 0"/>
      <geometry>
        <mesh filename="package://assets/p5_unified.stl"/>
      </geometry>
    </collision>
    <!-- Part uspa46_3 -->
    <visual>
      <origin xyz="0.044015 -0.027 0.0962" rpy="-3.14159 0 -0"/>
      <geometry>
        <mesh filename="package://assets/uspa46.stl"/>
      </geometry>
      <material name="uspa46_3_material">
        <color rgba="0.792157 0.819608 0.933333 1"/>
      </material>
    </visual>
    <collision>
      <origin xyz="0.044015 -0.027 0.0962" rpy="-3.14159 0 -0"/>
      <geometry>
        <mesh filename="package://assets/uspa46.stl"/>
      </geometry>
    </collision>
    <!-- Part leap_hand_xela_back_cover -->
    <visual>
      <origin xyz="-0.0293149 0.023 0.131221" rpy="-0 -1.5708 0"/>
      <geometry>
        <mesh filename="package://assets/leap_hand_xela_back_cover.stl"/>
      </geometry>
      <material name="leap_hand_xela_back_cover_material">
        <color rgba="0.792157 0.819608 0.933333 1"/>
      </material>
    </visual>
    <collision>
      <origin xyz="-0.0293149 0.023 0.131221" rpy="-0 -1.5708 0"/>
      <geometry>
        <mesh filename="package://assets/leap_hand_xela_back_cover.stl"/>
      </geometry>
    </collision>
    <!-- Part leap_hand_xela_side_cover -->
    <visual>
      <origin xyz="-0.0503368 0 0.110009" rpy="1.5708 0.00518834 -0"/>
      <geometry>
        <mesh filename="package://assets/leap_hand_xela_side_cover.stl"/>
      </geometry>
      <material name="leap_hand_xela_side_cover_material">
        <color rgba="0.792157 0.819608 0.933333 1"/>
      </material>
    </visual>
    <collision>
      <origin xyz="-0.0503368 0 0.110009" rpy="1.5708 0.00518834 -0"/>
      <geometry>
        <mesh filename="package://assets/leap_hand_xela_side_cover.stl"/>
      </geometry>
    </collision>
    <!-- Part leap_hand_xela_bottom -->
    <visual>
      <origin xyz="0 -0.023 0.0425" rpy="3.14159 0 3.14159"/>
      <geometry>
        <mesh filename="package://assets/leap_hand_xela_bottom.stl"/>
      </geometry>
      <material name="leap_hand_xela_bottom_material">
        <color rgba="0.792157 0.819608 0.933333 1"/>
      </material>
    </visual>
    <collision>
      <origin xyz="0 -0.023 0.0425" rpy="3.14159 0 3.14159"/>
      <geometry>
        <mesh filename="package://assets/leap_hand_xela_bottom.stl"/>
      </geometry>
    </collision>
    <!-- Part palm_face -->
    <visual>
      <origin xyz="-0.0283776 -0.029 0.131221" rpy="-0 -1.5708 0"/>
      <geometry>
        <mesh filename="package://assets/palm_face.stl"/>
      </geometry>
      <material name="palm_face_material">
        <color rgba="0.792157 0.819608 0.933333 1"/>
      </material>
    </visual>
    <collision>
      <origin xyz="-0.0283776 -0.029 0.131221" rpy="-0 -1.5708 0"/>
      <geometry>
        <mesh filename="package://assets/palm_face.stl"/>
      </geometry>
    </collision>
  </link>
  
  <link name="rf_p4_unified">
    <inertial>
      <origin xyz="0.0342889 -0.0265621 -0.0145004" rpy="0.0 0.0 0.0"/>
      <mass value="0.044"/>
      <inertia ixx="6.90801e-06" ixy="2.26365e-06" ixz="1.79475e-07" iyy="1.04766e-05" iyz="-1.82708e-07" izz="1.10431e-05"/>
    </inertial>
    <visual>
      <origin xyz="0.0048 -0.0 -0.0145" rpy="1.5708 1.5708 0.0"/>
      <geometry>
        <mesh filename="package://assets/p4_unified.stl"/>
      </geometry>
      <material name="p4_unified_material">
        <color rgba="0.972549 0.529412 0.00392157 1.0"/>
      </material>
    </visual>
    <collision>
      <origin xyz="0.0048 -0.0 -0.0145" rpy="1.5708 1.5708 0.0"/>
      <geometry>
        <mesh filename="package://assets/p4_unified.stl"/>
      </geometry>
    </collision>
  </link>

  <link name="rf_p3_unified">
    <inertial>
      <origin xyz="-0.000258994 0.00848001 0.0133488" rpy="0.0 0.0 0.0"/>
      <mass value="0.032"/>
      <inertia ixx="3.54425e-06" ixy="-1.6457e-08" ixz="-1.5221e-08" iyy="2.67248e-06" iyz="-1.71388e-07" izz="3.5384e-06"/>
    </inertial>
    <visual>
      <origin xyz="0.0 0.0075 0.0" rpy="-1.5708 -1.5708 0.0"/>
      <geometry>
        <mesh filename="package://assets/p3_unified.stl"/>
      </geometry>
      <material name="p3_unified_material">
        <color rgba="0.972549 0.529412 0.00392157 1.0"/>
      </material>
    </visual>
    <collision>
      <origin xyz="0.0 0.0075 0.0" rpy="-1.5708 -1.5708 0.0"/>
      <geometry>
        <mesh filename="package://assets/p3_unified.stl"/>
      </geometry>
    </collision>
  </link>

  <link name="rf_p2_unified">
    <inertial>
      <origin xyz="0.0304899 -0.00688132 -0.0146269" rpy="0.0 0.0 0.0"/>
      <mass value="0.037"/>
      <inertia ixx="8.11059e-06" ixy="5.66349e-07" ixz="1.88699e-07" iyy="6.98155e-06" iyz="-9.6344e-08" izz="9.0141e-06"/>
    </inertial>
    <visual>
      <origin xyz="0.00905 -0.0 -0.0145" rpy="1.5708 1.5708 0.0"/>
      <geometry>
        <mesh filename="package://assets/p2_unified.stl"/>
      </geometry>
      <material name="p2_unified_material">
        <color rgba="0.768627 0.886275 0.952941 1.0"/>
      </material>
    </visual>
    <collision>
      <origin xyz="0.00905 -0.0 -0.0145" rpy="1.5708 1.5708 0.0"/>
      <geometry>
        <mesh filename="package://assets/p2_unified.stl"/>
      </geometry>
    </collision>
  </link>

  <link name="rf_fingertop_unfied">
    <inertial>
      <origin xyz="-0.00193531 -0.0359351 0.0145854" rpy="0.0 0.0 0.0"/>
      <mass value="0.016"/>
      <inertia ixx="1.0779e-05" ixy="1.57487e-07" ixz="-2.8587e-08" iyy="5.55855e-06" iyz="-1.64744e-07" izz="1.00656e-05"/>
    </inertial>
    <visual>
      <origin xyz="-0.00135925 -0.025 0.0145" rpy="-1.5708 -1.5708 0.0"/>
      <geometry>
        <mesh filename="package://assets/fingertop_unfied.stl"/>
      </geometry>
      <material name="fingertop_unfied_material">
        <color rgba="0.917647 0.917647 0.917647 1.0"/>
      </material>
    </visual>
    <collision>
      <origin xyz="-0.00135925 -0.025 0.0145" rpy="-1.5708 -1.5708 0.0"/>
      <geometry>
        <mesh filename="package://assets/fingertop_unfied.stl"/>
      </geometry>
    </collision>
  </link>

  <link name="mf_p4_unified">
    <inertial>
      <origin xyz="0.0342889 -0.0265621 -0.0145004" rpy="0.0 0.0 0.0"/>
      <mass value="0.044"/>
      <inertia ixx="6.90801e-06" ixy="2.26365e-06" ixz="1.79475e-07" iyy="1.04766e-05" iyz="-1.82708e-07" izz="1.10431e-05"/>
    </inertial>
    <visual>
      <origin xyz="0.0048 -0.0 -0.0145" rpy="1.5708 1.5708 0.0"/>
      <geometry>
        <mesh filename="package://assets/p4_unified.stl"/>
      </geometry>
      <material name="p4_unified_material">
        <color rgba="0.972549 0.529412 0.00392157 1.0"/>
      </material>
    </visual>
    <collision>
      <origin xyz="0.0048 -0.0 -0.0145" rpy="1.5708 1.5708 0.0"/>
      <geometry>
        <mesh filename="package://assets/p4_unified.stl"/>
      </geometry>
    </collision>
  </link>

  <link name="mf_p3_unified">
    <inertial>
      <origin xyz="-0.000258994 0.00848001 0.0133488" rpy="0.0 0.0 0.0"/>
      <mass value="0.032"/>
      <inertia ixx="3.54425e-06" ixy="-1.6457e-08" ixz="-1.5221e-08" iyy="2.67248e-06" iyz="-1.71388e-07" izz="3.5384e-06"/>
    </inertial>
    <visual>
      <origin xyz="0.0 0.0075 0.0" rpy="-1.5708 -1.5708 0.0"/>
      <geometry>
        <mesh filename="package://assets/p3_unified.stl"/>
      </geometry>
      <material name="p3_unified_material">
        <color rgba="0.972549 0.529412 0.00392157 1.0"/>
      </material>
    </visual>
    <collision>
      <origin xyz="0.0 0.0075 0.0" rpy="-1.5708 -1.5708 0.0"/>
      <geometry>
        <mesh filename="package://assets/p3_unified.stl"/>
      </geometry>
    </collision>
  </link>

  <link name="mf_p2_unified">
    <inertial>
      <origin xyz="0.0304899 -0.00688132 -0.0146269" rpy="0.0 0.0 0.0"/>
      <mass value="0.037"/>
      <inertia ixx="8.11059e-06" ixy="5.66349e-07" ixz="1.88699e-07" iyy="6.98155e-06" iyz="-9.6344e-08" izz="9.0141e-06"/>
    </inertial>
    <visual>
      <origin xyz="0.00905 -0.0 -0.0145" rpy="1.5708 1.5708 0.0"/>
      <geometry>
        <mesh filename="package://assets/p2_unified.stl"/>
      </geometry>
      <material name="p2_unified_material">
        <color rgba="0.768627 0.886275 0.952941 1.0"/>
      </material>
    </visual>
    <collision>
      <origin xyz="0.00905 -0.0 -0.0145" rpy="1.5708 1.5708 0.0"/>
      <geometry>
        <mesh filename="package://assets/p2_unified.stl"/>
      </geometry>
    </collision>
  </link>

  <link name="mf_fingertop_unfied">
    <inertial>
      <origin xyz="-0.00193531 -0.0359351 0.0145854" rpy="0.0 0.0 0.0"/>
      <mass value="0.016"/>
      <inertia ixx="1.0779e-05" ixy="1.57487e-07" ixz="-2.8587e-08" iyy="5.55855e-06" iyz="-1.64744e-07" izz="1.00656e-05"/>
    </inertial>
    <visual>
      <origin xyz="-0.00135925 -0.025 0.0145" rpy="-1.5708 -1.5708 0.0"/>
      <geometry>
        <mesh filename="package://assets/fingertop_unfied.stl"/>
      </geometry>
      <material name="fingertop_unfied_material">
        <color rgba="0.917647 0.917647 0.917647 1.0"/>
      </material>
    </visual>
    <collision>
      <origin xyz="-0.00135925 -0.025 0.0145" rpy="-1.5708 -1.5708 0.0"/>
      <geometry>
        <mesh filename="package://assets/fingertop_unfied.stl"/>
      </geometry>
    </collision>
  </link>

  <link name="if_p4_unified">
    <inertial>
      <origin xyz="0.0342889 -0.0265621 -0.0145004" rpy="0.0 0.0 0.0"/>
      <mass value="0.044"/>
      <inertia ixx="6.90801e-06" ixy="2.26365e-06" ixz="1.79475e-07" iyy="1.04766e-05" iyz="-1.82708e-07" izz="1.10431e-05"/>
    </inertial>
    <visual>
      <origin xyz="0.0048 -0.0 -0.0145" rpy="1.5708 1.5708 0.0"/>
      <geometry>
        <mesh filename="package://assets/p4_unified.stl"/>
      </geometry>
      <material name="p4_unified_material">
        <color rgba="0.972549 0.529412 0.00392157 1.0"/>
      </material>
    </visual>
    <collision>
      <origin xyz="0.0048 -0.0 -0.0145" rpy="1.5708 1.5708 0.0"/>
      <geometry>
        <mesh filename="package://assets/p4_unified.stl"/>
      </geometry>
    </collision>
  </link>

  <link name="if_p3_unified">
    <inertial>
      <origin xyz="-0.000258994 0.00848001 0.0133488" rpy="0.0 0.0 0.0"/>
      <mass value="0.032"/>
      <inertia ixx="3.54425e-06" ixy="-1.6457e-08" ixz="-1.5221e-08" iyy="2.67248e-06" iyz="-1.71388e-07" izz="3.5384e-06"/>
    </inertial>
    <visual>
      <origin xyz="0.0 0.0075 0.0" rpy="-1.5708 -1.5708 0.0"/>
      <geometry>
        <mesh filename="package://assets/p3_unified.stl"/>
      </geometry>
      <material name="p3_unified_material">
        <color rgba="0.972549 0.529412 0.00392157 1.0"/>
      </material>
    </visual>
    <collision>
      <origin xyz="0.0 0.0075 0.0" rpy="-1.5708 -1.5708 0.0"/>
      <geometry>
        <mesh filename="package://assets/p3_unified.stl"/>
      </geometry>
    </collision>
  </link>

  <link name="if_p2_unified">
    <inertial>
      <origin xyz="0.0304899 -0.00688132 -0.0146269" rpy="0.0 0.0 0.0"/>
      <mass value="0.037"/>
      <inertia ixx="8.11059e-06" ixy="5.66349e-07" ixz="1.88699e-07" iyy="6.98155e-06" iyz="-9.6344e-08" izz="9.0141e-06"/>
    </inertial>
    <visual>
      <origin xyz="0.00905 -0.0 -0.0145" rpy="1.5708 1.5708 0.0"/>
      <geometry>
        <mesh filename="package://assets/p2_unified.stl"/>
      </geometry>
      <material name="p2_unified_material">
        <color rgba="0.768627 0.886275 0.952941 1.0"/>
      </material>
    </visual>
    <collision>
      <origin xyz="0.00905 -0.0 -0.0145" rpy="1.5708 1.5708 0.0"/>
      <geometry>
        <mesh filename="package://assets/p2_unified.stl"/>
      </geometry>
    </collision>
  </link>

  <link name="if_fingertop_unfied">
    <inertial>
      <origin xyz="-0.00193531 -0.0359351 0.0145854" rpy="0.0 0.0 0.0"/>
      <mass value="0.016"/>
      <inertia ixx="1.0779e-05" ixy="1.57487e-07" ixz="-2.8587e-08" iyy="5.55855e-06" iyz="-1.64744e-07" izz="1.00656e-05"/>
    </inertial>
    <visual>
      <origin xyz="-0.00135925 -0.025 0.0145" rpy="-1.5708 -1.5708 0.0"/>
      <geometry>
        <mesh filename="package://assets/fingertop_unfied.stl"/>
      </geometry>
      <material name="fingertop_unfied_material">
        <color rgba="0.917647 0.917647 0.917647 1.0"/>
      </material>
    </visual>
    <collision>
      <origin xyz="-0.00135925 -0.025 0.0145" rpy="-1.5708 -1.5708 0.0"/>
      <geometry>
        <mesh filename="package://assets/fingertop_unfied.stl"/>
      </geometry>
    </collision>
  </link>
  
  <link name="thp2_unified">
    <inertial>
      <origin xyz="-0.000232587 0.00882444 0.0117326" rpy="0.0 0.0 0.0"/>
      <mass value="0.032"/>
      <inertia ixx="3.63585e-06" ixy="2.0599e-08" ixz="8.412e-09" iyy="2.65288e-06" iyz="-1.4817e-08" izz="4.33226e-06"/>
    </inertial>

    <visual>
      <origin xyz="0.0 0.0075 0.0" rpy="-1.5708 -1.5708 0.0"/>
      <geometry>
        <mesh filename="package://assets/thp2_unified.stl"/>
      </geometry>
      <material name="thp2_unified_material">
        <color rgba="0.980392 0.713725 0.00392157 1.0"/>
      </material>
    </visual>

    <collision>
      <origin xyz="0.0 0.0075 0.0" rpy="-1.5708 -1.5708 0.0"/>
      <geometry>
        <mesh filename="package://assets/thp2_unified.stl"/>
      </geometry>
    </collision>
  </link>

  <link name="clipper">
    <inertial>
      <origin xyz="0.000911557 -0.00108086 0.00811114" rpy="0.0 0.0 0.0"/>
      <mass value="0.003"/>
      <inertia ixx="4.40805e-07" ixy="-4.612e-09" ixz="-4.6465e-08" iyy="1.184e-06" iyz="4.476e-09" izz="1.12942e-06"/>
    </inertial>

    <visual>
      <origin xyz="-0.0173 0.0 0.019" rpy="1.5708 -0.0 0.0"/>
      <geometry>
        <mesh filename="package://assets/thconnector.stl"/>
      </geometry>
      <material name="thconnector_material">
        <color rgba="0.792157 0.819608 0.933333 1.0"/>
      </material>
    </visual>

    <visual>
      <origin xyz="0.0155 -0.006 0.019" rpy="-3.14159 0.0 1.5708"/>
      <geometry>
        <mesh filename="package://assets/clipper.stl"/>
      </geometry>
      <material name="clipper_material">
        <color rgba="0.792157 0.819608 0.933333 1.0"/>
      </material>
    </visual>

    <collision>
      <origin xyz="-0.0173 0.0 0.019" rpy="1.5708 -0.0 0.0"/>
      <geometry>
        <mesh filename="package://assets/thconnector.stl"/>
      </geometry>
    </collision>

    <collision>
      <origin xyz="0.0155 -0.006 0.019" rpy="-3.14159 0.0 1.5708"/>
      <geometry>
        <mesh filename="package://assets/clipper.stl"/>
      </geometry>
    </collision>
  </link>

  <link name="thp1_unified">
    <inertial>
      <origin xyz="0.00144426 0.0112332 0.0144179" rpy="0.0 0.0 0.0"/>
      <mass value="0.038"/>
      <inertia ixx="7.98976e-06" ixy="8.1084e-08" ixz="-9.5788e-08" iyy="4.90108e-06" iyz="1.43138e-07" izz="7.77953e-06"/>
    </inertial>

    <visual>
      <origin xyz="-0.0 0.0245 0.0145" rpy="-0.0 -0.0 -0.0"/>
      <geometry>
        <mesh filename="package://assets/thp1_unified.stl"/>
      </geometry>
      <material name="thp1_unified_material">
        <color rgba="0.647059 0.647059 0.647059 1.0"/>
      </material>
    </visual>

    <collision>
      <origin xyz="-0.0 0.0245 0.0145" rpy="-0.0 -0.0 -0.0"/>
      <geometry>
        <mesh filename="package://assets/thp1_unified.stl"/>
      </geometry>
    </collision>
  </link>

  <link name="thfingertip_unified">
    <inertial>
      <origin xyz="-0.00210586 -0.0274158 0.0145397" rpy="0.0 0.0 0.0"/>
      <mass value="0.049"/>
      <inertia ixx="3.16029e-05" ixy="2.85926e-07" ixz="1.022e-07" iyy="8.51257e-06" iyz="-8.066e-08" izz="3.25689e-05"/>
    </inertial>

    <visual>
      <origin xyz="-0.0 -0.0275 0.014504" rpy="1.5708 0.0 -0.0"/>
      <geometry>
        <mesh filename="package://assets/thfingertip_unified.stl"/>
      </geometry>
      <material name="thfingertip_unified_material">
        <color rgba="0.498039 0.498039 0.498039 1.0"/>
      </material>
    </visual>

    <collision>
      <origin xyz="-0.0 -0.0275 0.014504" rpy="1.5708 0.0 -0.0"/>
      <geometry>
        <mesh filename="package://assets/thfingertip_unified.stl"/>
      </geometry>
    </collision>
  </link>
  
  <joint name="th_axl" type="revolute">
    <origin xyz="-0.0144 -0.0 0.013" rpy="-1.5708 0.0 1.5708"/>
    <parent link="thp2_unified"/>
    <child link="clipper"/>
    <axis xyz="0.0 0.0 1.0"/>
    <limit effort="10" velocity="10" lower="-0.349066" upper="2.0944"/>
  </joint>

  <joint name="th_mcp" type="revolute">
    <origin xyz="0.0145 -0.0 0.019" rpy="1.5708 0.0 -1.5708"/>
    <parent link="clipper"/>
    <child link="thp1_unified"/>
    <axis xyz="0.0 0.0 1.0"/>
    <limit effort="10" velocity="10" lower="-0.471239" upper="2.44346"/>
  </joint>

  <joint name="th_ipl" type="revolute">
    <origin xyz="-0.0 0.0446 0.0" rpy="-0.0 -0.0 -3.14159"/>
    <parent link="thp1_unified"/>
    <child link="thfingertip_unified"/>
    <axis xyz="0.0 0.0 1.0"/>
    <limit effort="10" velocity="10" lower="-1.3439" upper="1.88496"/>
  </joint>
  
  <joint name="rf_rot" type="revolute">
    <origin xyz="0.0326 -0.0123 -0.0145" rpy="-1.5708 -1.5708 0.0"/>
    <parent link="rf_p4_unified"/>
    <child link="rf_p3_unified"/>
    <axis xyz="0.0 0.0 1.0"/>
    <limit effort="10" velocity="10" lower="-1.0472" upper="1.0472"/>
  </joint>

  <joint name="rf_pip" type="revolute">
    <origin xyz="0.0145 0.015 0.013" rpy="1.5708 0.0 1.5708"/>
    <parent link="rf_p3_unified"/>
    <child link="rf_p2_unified"/>
    <axis xyz="0.0 0.0 1.0"/>
    <limit effort="10" velocity="10" lower="-0.506145" upper="1.88496"/>
  </joint>

  <joint name="rf_dip" type="revolute">
    <origin xyz="0.0361 0.0 -0.0291" rpy="0.0 0.0 1.5708"/>
    <parent link="rf_p2_unified"/>
    <child link="rf_fingertop_unfied"/>
    <axis xyz="0.0 0.0 1.0"/>
    <limit effort="10" velocity="10" lower="-0.366519" upper="2.04204"/>
  </joint>

  <joint name="mf_rot" type="revolute">
    <origin xyz="0.0326 -0.0123 -0.0145" rpy="-1.5708 -1.5708 0.0"/>
    <parent link="mf_p4_unified"/>
    <child link="mf_p3_unified"/>
    <axis xyz="0.0 0.0 1.0"/>
    <limit effort="10" velocity="10" lower="-1.0472" upper="1.0472"/>
  </joint>

  <joint name="mf_pip" type="revolute">
    <origin xyz="0.0145 0.015 0.013" rpy="1.5708 0.0 1.5708"/>
    <parent link="mf_p3_unified"/>
    <child link="mf_p2_unified"/>
    <axis xyz="0.0 0.0 1.0"/>
    <limit effort="10" velocity="10" lower="-0.506145" upper="1.88496"/>
  </joint>

  <joint name="mf_dip" type="revolute">
    <origin xyz="0.0361 0.0 -0.0291" rpy="0.0 0.0 1.5708"/>
    <parent link="mf_p2_unified"/>
    <child link="mf_fingertop_unfied"/>
    <axis xyz="0.0 0.0 1.0"/>
    <limit effort="10" velocity="10" lower="-0.366519" upper="2.04204"/>
  </joint>

  <joint name="if_rot" type="revolute">
    <origin xyz="0.0326 -0.0123 -0.0145" rpy="-1.5708 -1.5708 0.0"/>
    <parent link="if_p4_unified"/>
    <child link="if_p3_unified"/>
    <axis xyz="0.0 0.0 1.0"/>
    <limit effort="10" velocity="10" lower="-1.0472" upper="1.0472"/>
  </joint>

  <joint name="if_pip" type="revolute">
    <origin xyz="0.0145 0.015 0.013" rpy="1.5708 0.0 1.5708"/>
    <parent link="if_p3_unified"/>
    <child link="if_p2_unified"/>
    <axis xyz="0.0 0.0 1.0"/>
    <limit effort="10" velocity="10" lower="-0.506145" upper="1.88496"/>
  </joint>

  <joint name="if_dip" type="revolute">
    <origin xyz="0.0361 0.0 -0.0291" rpy="0.0 0.0 1.5708"/>
    <parent link="if_p2_unified"/>
    <child link="if_fingertop_unfied"/>
    <axis xyz="0.0 0.0 1.0"/>
    <limit effort="10" velocity="10" lower="-0.366519" upper="2.04204"/>
  </joint>
  
  <joint name="rf_mcp" type="revolute">
    <origin xyz="-0.02317 -0.0165 0.1436" rpy="3.14159 -1.5708 0.0"/>
    <parent link="leap_hand_xela_back_cover"/>
    <child link="rf_p4_unified"/>
    <axis xyz="0.0 0.0 1.0"/>
    <limit effort="10" velocity="10" lower="-0.314159" upper="2.23402"/>
  </joint>

  <joint name="mf_mcp" type="revolute">
    <origin xyz="0.02228 -0.0165 0.1436" rpy="3.14159 -1.5708 0.0"/>
    <parent link="leap_hand_xela_back_cover"/>
    <child link="mf_p4_unified"/>
    <axis xyz="0.0 0.0 1.0"/>
    <limit effort="10" velocity="10" lower="-0.314159" upper="2.23402"/>
  </joint>

  <joint name="if_mcp" type="revolute">
    <origin xyz="0.06773 -0.0165 0.1436" rpy="3.14159 -1.5708 0.0"/>
    <parent link="leap_hand_xela_back_cover"/>
    <child link="if_p4_unified"/>
    <axis xyz="0.0 0.0 1.0"/>
    <limit effort="10" velocity="10" lower="-0.314159" upper="2.23402"/>
  </joint>

  <joint name="th_cmc" type="revolute">
    <origin xyz="0.0480627 -0.013 0.07" rpy="-3.14159 0.0 3.14159"/>
    <parent link="leap_hand_xela_back_cover"/>
    <child link="thp2_unified"/>
    <axis xyz="0.0 0.0 1.0"/>
    <limit effort="10" velocity="10" lower="-0.349066" upper="2.0944"/>
  </joint>

  </robot>
  