<?xml version="1.0" ?>
<robot name="xela_thumb_generated">

  <link name="thp2_unified">
    <inertial>
      <origin xyz="-0.000232587 0.00882444 0.0117326" rpy="0.0 0.0 0.0"/>
      <mass value="0.032"/>
      <inertia ixx="3.63585e-06" ixy="2.0599e-08" ixz="8.412e-09" iyy="2.65288e-06" iyz="-1.4817e-08" izz="4.33226e-06"/>
    </inertial>

    <visual>
      <origin xyz="0.0 0.0075 0.0" rpy="-1.5708 -1.5708 0.0"/>
      <geometry>
        <mesh filename="package://assets/thp2_unified.stl"/>
      </geometry>
      <material name="thp2_unified_material">
        <color rgba="0.980392 0.713725 0.00392157 1.0"/>
      </material>
    </visual>

    <collision>
      <origin xyz="0.0 0.0075 0.0" rpy="-1.5708 -1.5708 0.0"/>
      <geometry>
        <mesh filename="package://assets/thp2_unified.stl"/>
      </geometry>
    </collision>
  </link>

  <link name="clipper">
    <inertial>
      <origin xyz="0.000911557 -0.00108086 0.00811114" rpy="0.0 0.0 0.0"/>
      <mass value="0.003"/>
      <inertia ixx="4.40805e-07" ixy="-4.612e-09" ixz="-4.6465e-08" iyy="1.184e-06" iyz="4.476e-09" izz="1.12942e-06"/>
    </inertial>

    <visual>
      <origin xyz="-0.0173 0.0 0.019" rpy="1.5708 -0.0 0.0"/>
      <geometry>
        <mesh filename="package://assets/thconnector.stl"/>
      </geometry>
      <material name="thconnector_material">
        <color rgba="0.792157 0.819608 0.933333 1.0"/>
      </material>
    </visual>

    <visual>
      <origin xyz="0.0155 -0.006 0.019" rpy="-3.14159 0.0 1.5708"/>
      <geometry>
        <mesh filename="package://assets/clipper.stl"/>
      </geometry>
      <material name="clipper_material">
        <color rgba="0.792157 0.819608 0.933333 1.0"/>
      </material>
    </visual>

    <collision>
      <origin xyz="-0.0173 0.0 0.019" rpy="1.5708 -0.0 0.0"/>
      <geometry>
        <mesh filename="package://assets/thconnector.stl"/>
      </geometry>
    </collision>

    <collision>
      <origin xyz="0.0155 -0.006 0.019" rpy="-3.14159 0.0 1.5708"/>
      <geometry>
        <mesh filename="package://assets/clipper.stl"/>
      </geometry>
    </collision>
  </link>

  <link name="thp1_unified">
    <inertial>
      <origin xyz="0.00144426 0.0112332 0.0144179" rpy="0.0 0.0 0.0"/>
      <mass value="0.038"/>
      <inertia ixx="7.98976e-06" ixy="8.1084e-08" ixz="-9.5788e-08" iyy="4.90108e-06" iyz="1.43138e-07" izz="7.77953e-06"/>
    </inertial>

    <visual>
      <origin xyz="-0.0 0.0245 0.0145" rpy="-0.0 -0.0 -0.0"/>
      <geometry>
        <mesh filename="package://assets/thp1_unified.stl"/>
      </geometry>
      <material name="thp1_unified_material">
        <color rgba="0.647059 0.647059 0.647059 1.0"/>
      </material>
    </visual>

    <collision>
      <origin xyz="-0.0 0.0245 0.0145" rpy="-0.0 -0.0 -0.0"/>
      <geometry>
        <mesh filename="package://assets/thp1_unified.stl"/>
      </geometry>
    </collision>
  </link>

  <link name="thfingertip_unified">
    <inertial>
      <origin xyz="-0.00210586 -0.0274158 0.0145397" rpy="0.0 0.0 0.0"/>
      <mass value="0.049"/>
      <inertia ixx="3.16029e-05" ixy="2.85926e-07" ixz="1.022e-07" iyy="8.51257e-06" iyz="-8.066e-08" izz="3.25689e-05"/>
    </inertial>

    <visual>
      <origin xyz="-0.0 -0.0275 0.014504" rpy="1.5708 0.0 -0.0"/>
      <geometry>
        <mesh filename="package://assets/thfingertip_unified.stl"/>
      </geometry>
      <material name="thfingertip_unified_material">
        <color rgba="0.498039 0.498039 0.498039 1.0"/>
      </material>
    </visual>

    <collision>
      <origin xyz="-0.0 -0.0275 0.014504" rpy="1.5708 0.0 -0.0"/>
      <geometry>
        <mesh filename="package://assets/thfingertip_unified.stl"/>
      </geometry>
    </collision>
  </link>

  <joint name="th_axl" type="revolute">
    <origin xyz="-0.0144 -0.0 0.013" rpy="-1.5708 0.0 1.5708"/>
    <parent link="thp2_unified"/>
    <child link="clipper"/>
    <axis xyz="0.0 0.0 1.0"/>
    <limit effort="10" velocity="10" lower="-0.349066" upper="2.0944"/>
  </joint>

  <joint name="th_mcp" type="revolute">
    <origin xyz="0.0145 -0.0 0.019" rpy="1.5708 0.0 -1.5708"/>
    <parent link="clipper"/>
    <child link="thp1_unified"/>
    <axis xyz="0.0 0.0 1.0"/>
    <limit effort="10" velocity="10" lower="-0.471239" upper="2.44346"/>
  </joint>

  <joint name="th_ipl" type="revolute">
    <origin xyz="-0.0 0.0446 0.0" rpy="-0.0 -0.0 -3.14159"/>
    <parent link="thp1_unified"/>
    <child link="thfingertip_unified"/>
    <axis xyz="0.0 0.0 1.0"/>
    <limit effort="10" velocity="10" lower="-1.3439" upper="1.88496"/>
  </joint>
<link name="base"/>
<joint name="base" type="fixed">
  <origin xyz="0 0 0.2" rpy="1.57 0 0"/>
  <parent link="base"/>
  <child link="thp2_unified"/>
</joint>
</robot>
