<?xml version="1.0" ?>
<robot name="xela_thumb_generated">

  <link name="cmc">
    <inertial>
      <origin xyz="0.0 0.0 0.0" rpy="0.0 0.0 0.0"/>
      <mass value="0.032"/>
      <inertia ixx="4.798e-06" ixy="1.2e-08" ixz="4e-09" iyy="2.862e-06" iyz="1.1e-08" izz="4.234e-06"/>
    </inertial>


    <visual>
      <origin xyz="-0.005356636907728671 0.0003 0.0007840340104173782" rpy="-1.5708 -1.5708 0.0"/>
      <geometry>
        <mesh filename="package://assets/pip.stl"/>
      </geometry>
      <material name="pip_material">
        <color rgba="0.74902 0.74902 0.74902 1.0"/>
      </material>
    </visual>
    


    <collision>
      <origin xyz="-0.005356636907728671 0.0003 0.0007840340104173782" rpy="-1.5708 -1.5708 0.0"/>
      <geometry>
        <mesh filename="package://assets/pip.stl"/>
      </geometry>
    </collision>
    
  </link>

  <link name="axl">
    <inertial>
      <origin xyz="0.0 0.0 0.0" rpy="0.0 0.0 0.0"/>
      <mass value="0.003"/>
      <inertia ixx="5.93e-07" ixy="0.0" ixz="0.0" iyy="5.49e-07" iyz="0.0" izz="2.24e-07"/>
    </inertial>


    <visual>
      <origin xyz="0.011961920770611187 0.0 -0.0158526489566642" rpy="1.5708 0.0 0.0"/>
      <geometry>
        <mesh filename="package://assets/thumb_pip.stl"/>
      </geometry>
      <material name="thumb_pip_material">
        <color rgba="0.866667 0.866667 0.0509804 1.0"/>
      </material>
    </visual>
    


    <collision>
      <origin xyz="0.011961920770611187 0.0 -0.0158526489566642" rpy="1.5708 0.0 0.0"/>
      <geometry>
        <mesh filename="package://assets/thumb_pip.stl"/>
      </geometry>
    </collision>
    
  </link>

  <link name="th_mcp">
    <inertial>
      <origin xyz="0.0 0.0 0.0" rpy="0.0 0.0 0.0"/>
      <mass value="0.038"/>
      <inertia ixx="8.474e-06" ixy="2.41e-07" ixz="2.6e-08" iyy="3.841e-06" iyz="2.5e-08" izz="7.679e-06"/>
    </inertial>


    <visual>
      <origin xyz="0.043968715707239175 0.0579529529737092 -0.008628676449369476" rpy="0.0 0.0 0.0"/>
      <geometry>
        <mesh filename="package://assets/thumb_dip.stl"/>
      </geometry>
      <material name="thumb_dip_material">
        <color rgba="0.866667 0.866667 0.0509804 1.0"/>
      </material>
    </visual>
    


    <collision>
      <origin xyz="0.043968715707239175 0.0579529529737092 -0.008628676449369476" rpy="0.0 0.0 0.0"/>
      <geometry>
        <mesh filename="package://assets/thumb_dip.stl"/>
      </geometry>
    </collision>
    
  </link>

  <link name="th_ipl">
    <inertial>
      <origin xyz="0.0 0.0 0.0" rpy="0.0 0.0 0.0"/>
      <mass value="0.049"/>
      <inertia ixx="2.0372e-05" ixy="-4.89e-07" ixz="-3e-08" iyy="4.336e-06" iyz="-9.7e-08" izz="1.9845e-05"/>
    </inertial>


    <visual>
      <origin xyz="0.06255953846266739 0.07845968291139699 0.048992911807332215" rpy="0.0 0.0 0.0"/>
      <geometry>
        <mesh filename="package://assets/thumb_fingertip.stl"/>
      </geometry>
      <material name="thumb_fingertip_material">
        <color rgba="0.603922 0.14902 0.14902 1.0"/>
      </material>
    </visual>
    


    <collision>
      <origin xyz="0.06255953846266739 0.07845968291139699 0.048992911807332215" rpy="0.0 0.0 0.0"/>
      <geometry>
        <mesh filename="package://assets/thumb_fingertip.stl"/>
      </geometry>
    </collision>
    
  </link>

  <link name="th_realtip">
    <inertial>
      <origin xyz="0.0 0.0 0.0" rpy="0.0 0.0 0.0"/>
      <mass value="0.1"/>
      <inertia ixx="2.5e-05" ixy="0.0" ixz="0.0" iyy="2.5e-05" iyz="0.0" izz="2.5e-05"/>
    </inertial>


    <visual>
      <origin xyz="0.0 0.0 0.0" rpy="0.0 0.0 0.0"/>
      <geometry>
        <sphere radius="0.005"/>
      </geometry>
      <material name="th_realtip_material">
        <color rgba="0.0 0.0 1.0 1.0"/>
      </material>
    </visual>
    


    <collision>
      <origin xyz="0.0 0.0 0.0" rpy="0.0 0.0 0.0"/>
      <geometry>
        <sphere radius="0.005"/>
      </geometry>
    </collision>
    
  </link>

  <joint name="th_axl" type="revolute">
    <origin xyz="-2.7755575615628914e-17 0.014300000000000005 -0.013000000000000012" rpy="1.570796326794896 -1.5707963267948963 0"/>
    <parent link="cmc"/>
    <child link="axl"/>
    <axis xyz="0 0 -1"/>
    <limit effort="0.95" velocity="8.48" lower="-0.47" upper="2.443"/>
  </joint>

  <joint name="th_mcp" type="revolute">
    <origin xyz="0 0.014499999999999966 -0.017000000000000053" rpy="-1.5707963267948966 1.6050198443300131e-46 -1.9721522630516625e-31"/>
    <parent link="axl"/>
    <child link="th_mcp"/>
    <axis xyz="0 0 -1"/>
    <limit effort="0.95" velocity="8.48" lower="-1.2" upper="1.9"/>
  </joint>

  <joint name="th_ipl" type="revolute">
    <origin xyz="-1.249000902703301e-16 0.046599999999999864 0.0001999999999999771" rpy="1.506395849149178e-44 5.423418723393526e-31 3.141592653589793"/>
    <parent link="th_mcp"/>
    <child link="th_ipl"/>
    <axis xyz="0 0 -1"/>
    <limit effort="0.95" velocity="8.48" lower="-1.34" upper="1.88"/>
  </joint>

  <joint name="th_realtip" type="fixed">
    <origin xyz="0.0 -0.07 -0.015" rpy="4.5935029425113685e-17 -2.8730071914463795e-16 4.439548105392361e-32"/>
    <parent link="th_ipl"/>
    <child link="th_realtip"/>
    <axis xyz="0 0 -1"/>
    
  </joint>
<link name="base"/>
<joint name="base" type="fixed">
  <origin xyz="0 0 0.2" rpy="1.57 0 0"/>
  <parent link="base"/>
  <child link="cmc"/>
</joint>
</robot>
