<?xml version="1.0" ?>
<!-- =================================================================================== -->
<!-- |    This document was autogenerated by xacro from /workspace/LeapXELA_Hardware_ws/ros_ws/src/xela_models/xela_models/urdf/4x6.xacro | -->
<!-- |    EDITING THIS FILE BY HAND IS NOT RECOMMENDED                                 | -->
<!-- =================================================================================== -->
<robot name="4x6">
  <!-- Rviz colors -->
  <material name="black">
    <color rgba="0.1 0.1 0.1 1.0"/>
  </material>
  <material name="blue">
    <color rgba="0.0 0.0 0.8 1.0"/>
  </material>
  <material name="green">
    <color rgba="0.0 0.8 0.0 1.0"/>
  </material>
  <material name="grey">
    <color rgba="0.2 0.2 0.2 1.0"/>
  </material>
  <material name="orange">
    <color rgba="1.0 0.4235294117647059 0.0392156862745098 1.0"/>
  </material>
  <material name="brown">
    <color rgba="0.8705882352941177 0.8117647058823529 0.7647058823529411 1.0"/>
  </material>
  <material name="red">
    <color rgba="0.8 0.0 0.0 1.0"/>
  </material>
  <material name="white">
    <color rgba="1.0 1.0 1.0 1.0"/>
  </material>
  <!-- Used for fixing robot to Gazebo 'base_link' -->
  <link name="world">
    <inertial>
      <mass value="0.005"/>
      <origin rpy="0 0 0" xyz="0 0 0"/>
      <inertia ixx="2e-07" ixy="0.0" ixz="0.0" iyy="2e-07" iyz="0.0" izz="2e-07"/>
    </inertial>
  </link>
  <!-- Base Link -->
  <joint name="fixed" type="fixed">
    <parent link="world"/>
    <child link="base_link"/>
  </joint>
  <link name="base_link">
    <visual>
      <geometry>
        <sphere radius="0.001"/>
      </geometry>
      <origin rpy="0 0 0" xyz="0.0 0.0 0.0"/>
    </visual>
    <collision>
      <geometry>
        <sphere radius="0.001"/>
      </geometry>
    </collision>
    <inertial>
      <mass value="0.005"/>
      <origin rpy="0 0 0" xyz="0 0 0"/>
      <inertia ixx="2e-07" ixy="0.0" ixz="0.0" iyy="2e-07" iyz="0.0" izz="2e-07"/>
    </inertial>
  </link>
  <joint name="1_4x6_fixed" type="fixed">
    <origin rpy="0.0 0.0 0.0" xyz="0.0 0.0 0.0"/>
    <parent link="base_link"/>
    <child link="1_4x6_base_link"/>
  </joint>
  <link name="1_4x6_base_link">
    <collision>
      <origin rpy="0 0 0" xyz="0 0 0"/>
      <geometry>
        <mesh filename="package://xela_models/mesh/4x6.stl"/>
      </geometry>
    </collision>
    <visual>
      <origin rpy="0 0 0" xyz="0 0 0"/>
      <geometry>
        <mesh filename="package://xela_models/mesh/4x6.stl"/>
      </geometry>
      <material name="red"/>
    </visual>
    <inertial>
      <mass value="0.005"/>
      <origin rpy="0 0 0" xyz="0 0 0"/>
      <inertia ixx="2e-07" ixy="0.0" ixz="0.0" iyy="2e-07" iyz="0.0" izz="2e-07"/>
    </inertial>
  </link>
  <link name="1_4x6_1_taxel_base_link">
    <visual>
      <geometry>
        <sphere radius="0.001"/>
      </geometry>
      <origin rpy="0 0 0" xyz="0.0 0.0 0.0"/>
      <material name="blue"/>
    </visual>
    <collision>
      <geometry>
        <sphere radius="0.001"/>
      </geometry>
    </collision>
    <inertial>
      <mass value="0.005"/>
      <origin rpy="0 0 0" xyz="0 0 0"/>
      <inertia ixx="2e-07" ixy="0.0" ixz="0.0" iyy="2e-07" iyz="0.0" izz="2e-07"/>
    </inertial>
  </link>
  <link name="1_4x6_1_base2x">
    <visual>
      <geometry>
        <sphere radius="0.0001"/>
      </geometry>
      <origin rpy="0 0 0" xyz="0.010239999999999999 0.026505 0.005"/>
      <material name="blue"/>
    </visual>
    <collision>
      <geometry>
        <sphere radius="0.0001"/>
      </geometry>
    </collision>
    <inertial>
      <mass value="0.005"/>
      <origin rpy="0 0 0" xyz="0 0 0"/>
      <inertia ixx="2e-07" ixy="0.0" ixz="0.0" iyy="2e-07" iyz="0.0" izz="2e-07"/>
    </inertial>
  </link>
  <link name="1_4x6_1_x2y">
    <visual>
      <geometry>
        <sphere radius="0.0001"/>
      </geometry>
      <origin rpy="0 0 0" xyz="0.0 0.0 0.0"/>
      <material name="blue"/>
    </visual>
    <collision>
      <geometry>
        <sphere radius="0.0001"/>
      </geometry>
    </collision>
    <inertial>
      <mass value="0.005"/>
      <origin rpy="0 0 0" xyz="0 0 0"/>
      <inertia ixx="2e-07" ixy="0.0" ixz="0.0" iyy="2e-07" iyz="0.0" izz="2e-07"/>
    </inertial>
  </link>
  <joint name="1_4x6_1_joint_x" type="prismatic">
    <origin rpy="0.0 0.0 0.0" xyz="0.010239999999999999 0.026505 0.005"/>
    <parent link="1_4x6_base_link"/>
    <child link="1_4x6_1_base2x"/>
    <axis xyz="1 0 0"/>
    <limit effort="100.0" lower="-0.0015" upper="0.0015" velocity="0.5"/>
  </joint>
  <joint name="1_4x6_1_joint_y" type="prismatic">
    <origin rpy="0.0 0.0 0.0" xyz="0.0 0.0 0.0"/>
    <parent link="1_4x6_1_base2x"/>
    <child link="1_4x6_1_x2y"/>
    <axis xyz="0 1 0"/>
    <limit effort="100.0" lower="-0.0015" upper="0.0015" velocity="0.5"/>
  </joint>
  <joint name="1_4x6_1_joint_z" type="prismatic">
    <origin rpy="0.0 0.0 0.0" xyz="0.0 0.0 0.0"/>
    <parent link="1_4x6_1_x2y"/>
    <child link="1_4x6_1_taxel_base_link"/>
    <axis xyz="0 0 1"/>
    <limit effort="100.0" lower="-0.001" upper="0.000" velocity="0.5"/>
  </joint>
  <link name="1_4x6_2_taxel_base_link">
    <visual>
      <geometry>
        <sphere radius="0.001"/>
      </geometry>
      <origin rpy="0 0 0" xyz="0.0 0.0 0.0"/>
      <material name="blue"/>
    </visual>
    <collision>
      <geometry>
        <sphere radius="0.001"/>
      </geometry>
    </collision>
    <inertial>
      <mass value="0.005"/>
      <origin rpy="0 0 0" xyz="0 0 0"/>
      <inertia ixx="2e-07" ixy="0.0" ixz="0.0" iyy="2e-07" iyz="0.0" izz="2e-07"/>
    </inertial>
  </link>
  <link name="1_4x6_2_base2x">
    <visual>
      <geometry>
        <sphere radius="0.0001"/>
      </geometry>
      <origin rpy="0 0 0" xyz="0.01748 0.026505 0.005"/>
      <material name="blue"/>
    </visual>
    <collision>
      <geometry>
        <sphere radius="0.0001"/>
      </geometry>
    </collision>
    <inertial>
      <mass value="0.005"/>
      <origin rpy="0 0 0" xyz="0 0 0"/>
      <inertia ixx="2e-07" ixy="0.0" ixz="0.0" iyy="2e-07" iyz="0.0" izz="2e-07"/>
    </inertial>
  </link>
  <link name="1_4x6_2_x2y">
    <visual>
      <geometry>
        <sphere radius="0.0001"/>
      </geometry>
      <origin rpy="0 0 0" xyz="0.0 0.0 0.0"/>
      <material name="blue"/>
    </visual>
    <collision>
      <geometry>
        <sphere radius="0.0001"/>
      </geometry>
    </collision>
    <inertial>
      <mass value="0.005"/>
      <origin rpy="0 0 0" xyz="0 0 0"/>
      <inertia ixx="2e-07" ixy="0.0" ixz="0.0" iyy="2e-07" iyz="0.0" izz="2e-07"/>
    </inertial>
  </link>
  <joint name="1_4x6_2_joint_x" type="prismatic">
    <origin rpy="0.0 0.0 0.0" xyz="0.01748 0.026505 0.005"/>
    <parent link="1_4x6_base_link"/>
    <child link="1_4x6_2_base2x"/>
    <axis xyz="1 0 0"/>
    <limit effort="100.0" lower="-0.0015" upper="0.0015" velocity="0.5"/>
  </joint>
  <joint name="1_4x6_2_joint_y" type="prismatic">
    <origin rpy="0.0 0.0 0.0" xyz="0.0 0.0 0.0"/>
    <parent link="1_4x6_2_base2x"/>
    <child link="1_4x6_2_x2y"/>
    <axis xyz="0 1 0"/>
    <limit effort="100.0" lower="-0.0015" upper="0.0015" velocity="0.5"/>
  </joint>
  <joint name="1_4x6_2_joint_z" type="prismatic">
    <origin rpy="0.0 0.0 0.0" xyz="0.0 0.0 0.0"/>
    <parent link="1_4x6_2_x2y"/>
    <child link="1_4x6_2_taxel_base_link"/>
    <axis xyz="0 0 1"/>
    <limit effort="100.0" lower="-0.001" upper="0.000" velocity="0.5"/>
  </joint>
  <link name="1_4x6_3_taxel_base_link">
    <visual>
      <geometry>
        <sphere radius="0.001"/>
      </geometry>
      <origin rpy="0 0 0" xyz="0.0 0.0 0.0"/>
      <material name="blue"/>
    </visual>
    <collision>
      <geometry>
        <sphere radius="0.001"/>
      </geometry>
    </collision>
    <inertial>
      <mass value="0.005"/>
      <origin rpy="0 0 0" xyz="0 0 0"/>
      <inertia ixx="2e-07" ixy="0.0" ixz="0.0" iyy="2e-07" iyz="0.0" izz="2e-07"/>
    </inertial>
  </link>
  <link name="1_4x6_3_base2x">
    <visual>
      <geometry>
        <sphere radius="0.0001"/>
      </geometry>
      <origin rpy="0 0 0" xyz="0.02472 0.026505 0.005"/>
      <material name="blue"/>
    </visual>
    <collision>
      <geometry>
        <sphere radius="0.0001"/>
      </geometry>
    </collision>
    <inertial>
      <mass value="0.005"/>
      <origin rpy="0 0 0" xyz="0 0 0"/>
      <inertia ixx="2e-07" ixy="0.0" ixz="0.0" iyy="2e-07" iyz="0.0" izz="2e-07"/>
    </inertial>
  </link>
  <link name="1_4x6_3_x2y">
    <visual>
      <geometry>
        <sphere radius="0.0001"/>
      </geometry>
      <origin rpy="0 0 0" xyz="0.0 0.0 0.0"/>
      <material name="blue"/>
    </visual>
    <collision>
      <geometry>
        <sphere radius="0.0001"/>
      </geometry>
    </collision>
    <inertial>
      <mass value="0.005"/>
      <origin rpy="0 0 0" xyz="0 0 0"/>
      <inertia ixx="2e-07" ixy="0.0" ixz="0.0" iyy="2e-07" iyz="0.0" izz="2e-07"/>
    </inertial>
  </link>
  <joint name="1_4x6_3_joint_x" type="prismatic">
    <origin rpy="0.0 0.0 0.0" xyz="0.02472 0.026505 0.005"/>
    <parent link="1_4x6_base_link"/>
    <child link="1_4x6_3_base2x"/>
    <axis xyz="1 0 0"/>
    <limit effort="100.0" lower="-0.0015" upper="0.0015" velocity="0.5"/>
  </joint>
  <joint name="1_4x6_3_joint_y" type="prismatic">
    <origin rpy="0.0 0.0 0.0" xyz="0.0 0.0 0.0"/>
    <parent link="1_4x6_3_base2x"/>
    <child link="1_4x6_3_x2y"/>
    <axis xyz="0 1 0"/>
    <limit effort="100.0" lower="-0.0015" upper="0.0015" velocity="0.5"/>
  </joint>
  <joint name="1_4x6_3_joint_z" type="prismatic">
    <origin rpy="0.0 0.0 0.0" xyz="0.0 0.0 0.0"/>
    <parent link="1_4x6_3_x2y"/>
    <child link="1_4x6_3_taxel_base_link"/>
    <axis xyz="0 0 1"/>
    <limit effort="100.0" lower="-0.001" upper="0.000" velocity="0.5"/>
  </joint>
  <link name="1_4x6_4_taxel_base_link">
    <visual>
      <geometry>
        <sphere radius="0.001"/>
      </geometry>
      <origin rpy="0 0 0" xyz="0.0 0.0 0.0"/>
      <material name="blue"/>
    </visual>
    <collision>
      <geometry>
        <sphere radius="0.001"/>
      </geometry>
    </collision>
    <inertial>
      <mass value="0.005"/>
      <origin rpy="0 0 0" xyz="0 0 0"/>
      <inertia ixx="2e-07" ixy="0.0" ixz="0.0" iyy="2e-07" iyz="0.0" izz="2e-07"/>
    </inertial>
  </link>
  <link name="1_4x6_4_base2x">
    <visual>
      <geometry>
        <sphere radius="0.0001"/>
      </geometry>
      <origin rpy="0 0 0" xyz="0.03196 0.026505 0.005"/>
      <material name="blue"/>
    </visual>
    <collision>
      <geometry>
        <sphere radius="0.0001"/>
      </geometry>
    </collision>
    <inertial>
      <mass value="0.005"/>
      <origin rpy="0 0 0" xyz="0 0 0"/>
      <inertia ixx="2e-07" ixy="0.0" ixz="0.0" iyy="2e-07" iyz="0.0" izz="2e-07"/>
    </inertial>
  </link>
  <link name="1_4x6_4_x2y">
    <visual>
      <geometry>
        <sphere radius="0.0001"/>
      </geometry>
      <origin rpy="0 0 0" xyz="0.0 0.0 0.0"/>
      <material name="blue"/>
    </visual>
    <collision>
      <geometry>
        <sphere radius="0.0001"/>
      </geometry>
    </collision>
    <inertial>
      <mass value="0.005"/>
      <origin rpy="0 0 0" xyz="0 0 0"/>
      <inertia ixx="2e-07" ixy="0.0" ixz="0.0" iyy="2e-07" iyz="0.0" izz="2e-07"/>
    </inertial>
  </link>
  <joint name="1_4x6_4_joint_x" type="prismatic">
    <origin rpy="0.0 0.0 0.0" xyz="0.03196 0.026505 0.005"/>
    <parent link="1_4x6_base_link"/>
    <child link="1_4x6_4_base2x"/>
    <axis xyz="1 0 0"/>
    <limit effort="100.0" lower="-0.0015" upper="0.0015" velocity="0.5"/>
  </joint>
  <joint name="1_4x6_4_joint_y" type="prismatic">
    <origin rpy="0.0 0.0 0.0" xyz="0.0 0.0 0.0"/>
    <parent link="1_4x6_4_base2x"/>
    <child link="1_4x6_4_x2y"/>
    <axis xyz="0 1 0"/>
    <limit effort="100.0" lower="-0.0015" upper="0.0015" velocity="0.5"/>
  </joint>
  <joint name="1_4x6_4_joint_z" type="prismatic">
    <origin rpy="0.0 0.0 0.0" xyz="0.0 0.0 0.0"/>
    <parent link="1_4x6_4_x2y"/>
    <child link="1_4x6_4_taxel_base_link"/>
    <axis xyz="0 0 1"/>
    <limit effort="100.0" lower="-0.001" upper="0.000" velocity="0.5"/>
  </joint>
  <link name="1_4x6_5_taxel_base_link">
    <visual>
      <geometry>
        <sphere radius="0.001"/>
      </geometry>
      <origin rpy="0 0 0" xyz="0.0 0.0 0.0"/>
      <material name="blue"/>
    </visual>
    <collision>
      <geometry>
        <sphere radius="0.001"/>
      </geometry>
    </collision>
    <inertial>
      <mass value="0.005"/>
      <origin rpy="0 0 0" xyz="0 0 0"/>
      <inertia ixx="2e-07" ixy="0.0" ixz="0.0" iyy="2e-07" iyz="0.0" izz="2e-07"/>
    </inertial>
  </link>
  <link name="1_4x6_5_base2x">
    <visual>
      <geometry>
        <sphere radius="0.0001"/>
      </geometry>
      <origin rpy="0 0 0" xyz="0.0392 0.026505 0.005"/>
      <material name="blue"/>
    </visual>
    <collision>
      <geometry>
        <sphere radius="0.0001"/>
      </geometry>
    </collision>
    <inertial>
      <mass value="0.005"/>
      <origin rpy="0 0 0" xyz="0 0 0"/>
      <inertia ixx="2e-07" ixy="0.0" ixz="0.0" iyy="2e-07" iyz="0.0" izz="2e-07"/>
    </inertial>
  </link>
  <link name="1_4x6_5_x2y">
    <visual>
      <geometry>
        <sphere radius="0.0001"/>
      </geometry>
      <origin rpy="0 0 0" xyz="0.0 0.0 0.0"/>
      <material name="blue"/>
    </visual>
    <collision>
      <geometry>
        <sphere radius="0.0001"/>
      </geometry>
    </collision>
    <inertial>
      <mass value="0.005"/>
      <origin rpy="0 0 0" xyz="0 0 0"/>
      <inertia ixx="2e-07" ixy="0.0" ixz="0.0" iyy="2e-07" iyz="0.0" izz="2e-07"/>
    </inertial>
  </link>
  <joint name="1_4x6_5_joint_x" type="prismatic">
    <origin rpy="0.0 0.0 0.0" xyz="0.0392 0.026505 0.005"/>
    <parent link="1_4x6_base_link"/>
    <child link="1_4x6_5_base2x"/>
    <axis xyz="1 0 0"/>
    <limit effort="100.0" lower="-0.0015" upper="0.0015" velocity="0.5"/>
  </joint>
  <joint name="1_4x6_5_joint_y" type="prismatic">
    <origin rpy="0.0 0.0 0.0" xyz="0.0 0.0 0.0"/>
    <parent link="1_4x6_5_base2x"/>
    <child link="1_4x6_5_x2y"/>
    <axis xyz="0 1 0"/>
    <limit effort="100.0" lower="-0.0015" upper="0.0015" velocity="0.5"/>
  </joint>
  <joint name="1_4x6_5_joint_z" type="prismatic">
    <origin rpy="0.0 0.0 0.0" xyz="0.0 0.0 0.0"/>
    <parent link="1_4x6_5_x2y"/>
    <child link="1_4x6_5_taxel_base_link"/>
    <axis xyz="0 0 1"/>
    <limit effort="100.0" lower="-0.001" upper="0.000" velocity="0.5"/>
  </joint>
  <link name="1_4x6_6_taxel_base_link">
    <visual>
      <geometry>
        <sphere radius="0.001"/>
      </geometry>
      <origin rpy="0 0 0" xyz="0.0 0.0 0.0"/>
      <material name="blue"/>
    </visual>
    <collision>
      <geometry>
        <sphere radius="0.001"/>
      </geometry>
    </collision>
    <inertial>
      <mass value="0.005"/>
      <origin rpy="0 0 0" xyz="0 0 0"/>
      <inertia ixx="2e-07" ixy="0.0" ixz="0.0" iyy="2e-07" iyz="0.0" izz="2e-07"/>
    </inertial>
  </link>
  <link name="1_4x6_6_base2x">
    <visual>
      <geometry>
        <sphere radius="0.0001"/>
      </geometry>
      <origin rpy="0 0 0" xyz="0.04644 0.026505 0.005"/>
      <material name="blue"/>
    </visual>
    <collision>
      <geometry>
        <sphere radius="0.0001"/>
      </geometry>
    </collision>
    <inertial>
      <mass value="0.005"/>
      <origin rpy="0 0 0" xyz="0 0 0"/>
      <inertia ixx="2e-07" ixy="0.0" ixz="0.0" iyy="2e-07" iyz="0.0" izz="2e-07"/>
    </inertial>
  </link>
  <link name="1_4x6_6_x2y">
    <visual>
      <geometry>
        <sphere radius="0.0001"/>
      </geometry>
      <origin rpy="0 0 0" xyz="0.0 0.0 0.0"/>
      <material name="blue"/>
    </visual>
    <collision>
      <geometry>
        <sphere radius="0.0001"/>
      </geometry>
    </collision>
    <inertial>
      <mass value="0.005"/>
      <origin rpy="0 0 0" xyz="0 0 0"/>
      <inertia ixx="2e-07" ixy="0.0" ixz="0.0" iyy="2e-07" iyz="0.0" izz="2e-07"/>
    </inertial>
  </link>
  <joint name="1_4x6_6_joint_x" type="prismatic">
    <origin rpy="0.0 0.0 0.0" xyz="0.04644 0.026505 0.005"/>
    <parent link="1_4x6_base_link"/>
    <child link="1_4x6_6_base2x"/>
    <axis xyz="1 0 0"/>
    <limit effort="100.0" lower="-0.0015" upper="0.0015" velocity="0.5"/>
  </joint>
  <joint name="1_4x6_6_joint_y" type="prismatic">
    <origin rpy="0.0 0.0 0.0" xyz="0.0 0.0 0.0"/>
    <parent link="1_4x6_6_base2x"/>
    <child link="1_4x6_6_x2y"/>
    <axis xyz="0 1 0"/>
    <limit effort="100.0" lower="-0.0015" upper="0.0015" velocity="0.5"/>
  </joint>
  <joint name="1_4x6_6_joint_z" type="prismatic">
    <origin rpy="0.0 0.0 0.0" xyz="0.0 0.0 0.0"/>
    <parent link="1_4x6_6_x2y"/>
    <child link="1_4x6_6_taxel_base_link"/>
    <axis xyz="0 0 1"/>
    <limit effort="100.0" lower="-0.001" upper="0.000" velocity="0.5"/>
  </joint>
  <link name="1_4x6_7_taxel_base_link">
    <visual>
      <geometry>
        <sphere radius="0.001"/>
      </geometry>
      <origin rpy="0 0 0" xyz="0.0 0.0 0.0"/>
      <material name="blue"/>
    </visual>
    <collision>
      <geometry>
        <sphere radius="0.001"/>
      </geometry>
    </collision>
    <inertial>
      <mass value="0.005"/>
      <origin rpy="0 0 0" xyz="0 0 0"/>
      <inertia ixx="2e-07" ixy="0.0" ixz="0.0" iyy="2e-07" iyz="0.0" izz="2e-07"/>
    </inertial>
  </link>
  <link name="1_4x6_7_base2x">
    <visual>
      <geometry>
        <sphere radius="0.0001"/>
      </geometry>
      <origin rpy="0 0 0" xyz="0.010239999999999999 0.019335 0.005"/>
      <material name="blue"/>
    </visual>
    <collision>
      <geometry>
        <sphere radius="0.0001"/>
      </geometry>
    </collision>
    <inertial>
      <mass value="0.005"/>
      <origin rpy="0 0 0" xyz="0 0 0"/>
      <inertia ixx="2e-07" ixy="0.0" ixz="0.0" iyy="2e-07" iyz="0.0" izz="2e-07"/>
    </inertial>
  </link>
  <link name="1_4x6_7_x2y">
    <visual>
      <geometry>
        <sphere radius="0.0001"/>
      </geometry>
      <origin rpy="0 0 0" xyz="0.0 0.0 0.0"/>
      <material name="blue"/>
    </visual>
    <collision>
      <geometry>
        <sphere radius="0.0001"/>
      </geometry>
    </collision>
    <inertial>
      <mass value="0.005"/>
      <origin rpy="0 0 0" xyz="0 0 0"/>
      <inertia ixx="2e-07" ixy="0.0" ixz="0.0" iyy="2e-07" iyz="0.0" izz="2e-07"/>
    </inertial>
  </link>
  <joint name="1_4x6_7_joint_x" type="prismatic">
    <origin rpy="0.0 0.0 0.0" xyz="0.010239999999999999 0.019335 0.005"/>
    <parent link="1_4x6_base_link"/>
    <child link="1_4x6_7_base2x"/>
    <axis xyz="1 0 0"/>
    <limit effort="100.0" lower="-0.0015" upper="0.0015" velocity="0.5"/>
  </joint>
  <joint name="1_4x6_7_joint_y" type="prismatic">
    <origin rpy="0.0 0.0 0.0" xyz="0.0 0.0 0.0"/>
    <parent link="1_4x6_7_base2x"/>
    <child link="1_4x6_7_x2y"/>
    <axis xyz="0 1 0"/>
    <limit effort="100.0" lower="-0.0015" upper="0.0015" velocity="0.5"/>
  </joint>
  <joint name="1_4x6_7_joint_z" type="prismatic">
    <origin rpy="0.0 0.0 0.0" xyz="0.0 0.0 0.0"/>
    <parent link="1_4x6_7_x2y"/>
    <child link="1_4x6_7_taxel_base_link"/>
    <axis xyz="0 0 1"/>
    <limit effort="100.0" lower="-0.001" upper="0.000" velocity="0.5"/>
  </joint>
  <link name="1_4x6_8_taxel_base_link">
    <visual>
      <geometry>
        <sphere radius="0.001"/>
      </geometry>
      <origin rpy="0 0 0" xyz="0.0 0.0 0.0"/>
      <material name="blue"/>
    </visual>
    <collision>
      <geometry>
        <sphere radius="0.001"/>
      </geometry>
    </collision>
    <inertial>
      <mass value="0.005"/>
      <origin rpy="0 0 0" xyz="0 0 0"/>
      <inertia ixx="2e-07" ixy="0.0" ixz="0.0" iyy="2e-07" iyz="0.0" izz="2e-07"/>
    </inertial>
  </link>
  <link name="1_4x6_8_base2x">
    <visual>
      <geometry>
        <sphere radius="0.0001"/>
      </geometry>
      <origin rpy="0 0 0" xyz="0.01748 0.019335 0.005"/>
      <material name="blue"/>
    </visual>
    <collision>
      <geometry>
        <sphere radius="0.0001"/>
      </geometry>
    </collision>
    <inertial>
      <mass value="0.005"/>
      <origin rpy="0 0 0" xyz="0 0 0"/>
      <inertia ixx="2e-07" ixy="0.0" ixz="0.0" iyy="2e-07" iyz="0.0" izz="2e-07"/>
    </inertial>
  </link>
  <link name="1_4x6_8_x2y">
    <visual>
      <geometry>
        <sphere radius="0.0001"/>
      </geometry>
      <origin rpy="0 0 0" xyz="0.0 0.0 0.0"/>
      <material name="blue"/>
    </visual>
    <collision>
      <geometry>
        <sphere radius="0.0001"/>
      </geometry>
    </collision>
    <inertial>
      <mass value="0.005"/>
      <origin rpy="0 0 0" xyz="0 0 0"/>
      <inertia ixx="2e-07" ixy="0.0" ixz="0.0" iyy="2e-07" iyz="0.0" izz="2e-07"/>
    </inertial>
  </link>
  <joint name="1_4x6_8_joint_x" type="prismatic">
    <origin rpy="0.0 0.0 0.0" xyz="0.01748 0.019335 0.005"/>
    <parent link="1_4x6_base_link"/>
    <child link="1_4x6_8_base2x"/>
    <axis xyz="1 0 0"/>
    <limit effort="100.0" lower="-0.0015" upper="0.0015" velocity="0.5"/>
  </joint>
  <joint name="1_4x6_8_joint_y" type="prismatic">
    <origin rpy="0.0 0.0 0.0" xyz="0.0 0.0 0.0"/>
    <parent link="1_4x6_8_base2x"/>
    <child link="1_4x6_8_x2y"/>
    <axis xyz="0 1 0"/>
    <limit effort="100.0" lower="-0.0015" upper="0.0015" velocity="0.5"/>
  </joint>
  <joint name="1_4x6_8_joint_z" type="prismatic">
    <origin rpy="0.0 0.0 0.0" xyz="0.0 0.0 0.0"/>
    <parent link="1_4x6_8_x2y"/>
    <child link="1_4x6_8_taxel_base_link"/>
    <axis xyz="0 0 1"/>
    <limit effort="100.0" lower="-0.001" upper="0.000" velocity="0.5"/>
  </joint>
  <link name="1_4x6_9_taxel_base_link">
    <visual>
      <geometry>
        <sphere radius="0.001"/>
      </geometry>
      <origin rpy="0 0 0" xyz="0.0 0.0 0.0"/>
      <material name="blue"/>
    </visual>
    <collision>
      <geometry>
        <sphere radius="0.001"/>
      </geometry>
    </collision>
    <inertial>
      <mass value="0.005"/>
      <origin rpy="0 0 0" xyz="0 0 0"/>
      <inertia ixx="2e-07" ixy="0.0" ixz="0.0" iyy="2e-07" iyz="0.0" izz="2e-07"/>
    </inertial>
  </link>
  <link name="1_4x6_9_base2x">
    <visual>
      <geometry>
        <sphere radius="0.0001"/>
      </geometry>
      <origin rpy="0 0 0" xyz="0.02472 0.019335 0.005"/>
      <material name="blue"/>
    </visual>
    <collision>
      <geometry>
        <sphere radius="0.0001"/>
      </geometry>
    </collision>
    <inertial>
      <mass value="0.005"/>
      <origin rpy="0 0 0" xyz="0 0 0"/>
      <inertia ixx="2e-07" ixy="0.0" ixz="0.0" iyy="2e-07" iyz="0.0" izz="2e-07"/>
    </inertial>
  </link>
  <link name="1_4x6_9_x2y">
    <visual>
      <geometry>
        <sphere radius="0.0001"/>
      </geometry>
      <origin rpy="0 0 0" xyz="0.0 0.0 0.0"/>
      <material name="blue"/>
    </visual>
    <collision>
      <geometry>
        <sphere radius="0.0001"/>
      </geometry>
    </collision>
    <inertial>
      <mass value="0.005"/>
      <origin rpy="0 0 0" xyz="0 0 0"/>
      <inertia ixx="2e-07" ixy="0.0" ixz="0.0" iyy="2e-07" iyz="0.0" izz="2e-07"/>
    </inertial>
  </link>
  <joint name="1_4x6_9_joint_x" type="prismatic">
    <origin rpy="0.0 0.0 0.0" xyz="0.02472 0.019335 0.005"/>
    <parent link="1_4x6_base_link"/>
    <child link="1_4x6_9_base2x"/>
    <axis xyz="1 0 0"/>
    <limit effort="100.0" lower="-0.0015" upper="0.0015" velocity="0.5"/>
  </joint>
  <joint name="1_4x6_9_joint_y" type="prismatic">
    <origin rpy="0.0 0.0 0.0" xyz="0.0 0.0 0.0"/>
    <parent link="1_4x6_9_base2x"/>
    <child link="1_4x6_9_x2y"/>
    <axis xyz="0 1 0"/>
    <limit effort="100.0" lower="-0.0015" upper="0.0015" velocity="0.5"/>
  </joint>
  <joint name="1_4x6_9_joint_z" type="prismatic">
    <origin rpy="0.0 0.0 0.0" xyz="0.0 0.0 0.0"/>
    <parent link="1_4x6_9_x2y"/>
    <child link="1_4x6_9_taxel_base_link"/>
    <axis xyz="0 0 1"/>
    <limit effort="100.0" lower="-0.001" upper="0.000" velocity="0.5"/>
  </joint>
  <link name="1_4x6_10_taxel_base_link">
    <visual>
      <geometry>
        <sphere radius="0.001"/>
      </geometry>
      <origin rpy="0 0 0" xyz="0.0 0.0 0.0"/>
      <material name="blue"/>
    </visual>
    <collision>
      <geometry>
        <sphere radius="0.001"/>
      </geometry>
    </collision>
    <inertial>
      <mass value="0.005"/>
      <origin rpy="0 0 0" xyz="0 0 0"/>
      <inertia ixx="2e-07" ixy="0.0" ixz="0.0" iyy="2e-07" iyz="0.0" izz="2e-07"/>
    </inertial>
  </link>
  <link name="1_4x6_10_base2x">
    <visual>
      <geometry>
        <sphere radius="0.0001"/>
      </geometry>
      <origin rpy="0 0 0" xyz="0.03196 0.019335 0.005"/>
      <material name="blue"/>
    </visual>
    <collision>
      <geometry>
        <sphere radius="0.0001"/>
      </geometry>
    </collision>
    <inertial>
      <mass value="0.005"/>
      <origin rpy="0 0 0" xyz="0 0 0"/>
      <inertia ixx="2e-07" ixy="0.0" ixz="0.0" iyy="2e-07" iyz="0.0" izz="2e-07"/>
    </inertial>
  </link>
  <link name="1_4x6_10_x2y">
    <visual>
      <geometry>
        <sphere radius="0.0001"/>
      </geometry>
      <origin rpy="0 0 0" xyz="0.0 0.0 0.0"/>
      <material name="blue"/>
    </visual>
    <collision>
      <geometry>
        <sphere radius="0.0001"/>
      </geometry>
    </collision>
    <inertial>
      <mass value="0.005"/>
      <origin rpy="0 0 0" xyz="0 0 0"/>
      <inertia ixx="2e-07" ixy="0.0" ixz="0.0" iyy="2e-07" iyz="0.0" izz="2e-07"/>
    </inertial>
  </link>
  <joint name="1_4x6_10_joint_x" type="prismatic">
    <origin rpy="0.0 0.0 0.0" xyz="0.03196 0.019335 0.005"/>
    <parent link="1_4x6_base_link"/>
    <child link="1_4x6_10_base2x"/>
    <axis xyz="1 0 0"/>
    <limit effort="100.0" lower="-0.0015" upper="0.0015" velocity="0.5"/>
  </joint>
  <joint name="1_4x6_10_joint_y" type="prismatic">
    <origin rpy="0.0 0.0 0.0" xyz="0.0 0.0 0.0"/>
    <parent link="1_4x6_10_base2x"/>
    <child link="1_4x6_10_x2y"/>
    <axis xyz="0 1 0"/>
    <limit effort="100.0" lower="-0.0015" upper="0.0015" velocity="0.5"/>
  </joint>
  <joint name="1_4x6_10_joint_z" type="prismatic">
    <origin rpy="0.0 0.0 0.0" xyz="0.0 0.0 0.0"/>
    <parent link="1_4x6_10_x2y"/>
    <child link="1_4x6_10_taxel_base_link"/>
    <axis xyz="0 0 1"/>
    <limit effort="100.0" lower="-0.001" upper="0.000" velocity="0.5"/>
  </joint>
  <link name="1_4x6_11_taxel_base_link">
    <visual>
      <geometry>
        <sphere radius="0.001"/>
      </geometry>
      <origin rpy="0 0 0" xyz="0.0 0.0 0.0"/>
      <material name="blue"/>
    </visual>
    <collision>
      <geometry>
        <sphere radius="0.001"/>
      </geometry>
    </collision>
    <inertial>
      <mass value="0.005"/>
      <origin rpy="0 0 0" xyz="0 0 0"/>
      <inertia ixx="2e-07" ixy="0.0" ixz="0.0" iyy="2e-07" iyz="0.0" izz="2e-07"/>
    </inertial>
  </link>
  <link name="1_4x6_11_base2x">
    <visual>
      <geometry>
        <sphere radius="0.0001"/>
      </geometry>
      <origin rpy="0 0 0" xyz="0.0392 0.019335 0.005"/>
      <material name="blue"/>
    </visual>
    <collision>
      <geometry>
        <sphere radius="0.0001"/>
      </geometry>
    </collision>
    <inertial>
      <mass value="0.005"/>
      <origin rpy="0 0 0" xyz="0 0 0"/>
      <inertia ixx="2e-07" ixy="0.0" ixz="0.0" iyy="2e-07" iyz="0.0" izz="2e-07"/>
    </inertial>
  </link>
  <link name="1_4x6_11_x2y">
    <visual>
      <geometry>
        <sphere radius="0.0001"/>
      </geometry>
      <origin rpy="0 0 0" xyz="0.0 0.0 0.0"/>
      <material name="blue"/>
    </visual>
    <collision>
      <geometry>
        <sphere radius="0.0001"/>
      </geometry>
    </collision>
    <inertial>
      <mass value="0.005"/>
      <origin rpy="0 0 0" xyz="0 0 0"/>
      <inertia ixx="2e-07" ixy="0.0" ixz="0.0" iyy="2e-07" iyz="0.0" izz="2e-07"/>
    </inertial>
  </link>
  <joint name="1_4x6_11_joint_x" type="prismatic">
    <origin rpy="0.0 0.0 0.0" xyz="0.0392 0.019335 0.005"/>
    <parent link="1_4x6_base_link"/>
    <child link="1_4x6_11_base2x"/>
    <axis xyz="1 0 0"/>
    <limit effort="100.0" lower="-0.0015" upper="0.0015" velocity="0.5"/>
  </joint>
  <joint name="1_4x6_11_joint_y" type="prismatic">
    <origin rpy="0.0 0.0 0.0" xyz="0.0 0.0 0.0"/>
    <parent link="1_4x6_11_base2x"/>
    <child link="1_4x6_11_x2y"/>
    <axis xyz="0 1 0"/>
    <limit effort="100.0" lower="-0.0015" upper="0.0015" velocity="0.5"/>
  </joint>
  <joint name="1_4x6_11_joint_z" type="prismatic">
    <origin rpy="0.0 0.0 0.0" xyz="0.0 0.0 0.0"/>
    <parent link="1_4x6_11_x2y"/>
    <child link="1_4x6_11_taxel_base_link"/>
    <axis xyz="0 0 1"/>
    <limit effort="100.0" lower="-0.001" upper="0.000" velocity="0.5"/>
  </joint>
  <link name="1_4x6_12_taxel_base_link">
    <visual>
      <geometry>
        <sphere radius="0.001"/>
      </geometry>
      <origin rpy="0 0 0" xyz="0.0 0.0 0.0"/>
      <material name="blue"/>
    </visual>
    <collision>
      <geometry>
        <sphere radius="0.001"/>
      </geometry>
    </collision>
    <inertial>
      <mass value="0.005"/>
      <origin rpy="0 0 0" xyz="0 0 0"/>
      <inertia ixx="2e-07" ixy="0.0" ixz="0.0" iyy="2e-07" iyz="0.0" izz="2e-07"/>
    </inertial>
  </link>
  <link name="1_4x6_12_base2x">
    <visual>
      <geometry>
        <sphere radius="0.0001"/>
      </geometry>
      <origin rpy="0 0 0" xyz="0.04644 0.019335 0.005"/>
      <material name="blue"/>
    </visual>
    <collision>
      <geometry>
        <sphere radius="0.0001"/>
      </geometry>
    </collision>
    <inertial>
      <mass value="0.005"/>
      <origin rpy="0 0 0" xyz="0 0 0"/>
      <inertia ixx="2e-07" ixy="0.0" ixz="0.0" iyy="2e-07" iyz="0.0" izz="2e-07"/>
    </inertial>
  </link>
  <link name="1_4x6_12_x2y">
    <visual>
      <geometry>
        <sphere radius="0.0001"/>
      </geometry>
      <origin rpy="0 0 0" xyz="0.0 0.0 0.0"/>
      <material name="blue"/>
    </visual>
    <collision>
      <geometry>
        <sphere radius="0.0001"/>
      </geometry>
    </collision>
    <inertial>
      <mass value="0.005"/>
      <origin rpy="0 0 0" xyz="0 0 0"/>
      <inertia ixx="2e-07" ixy="0.0" ixz="0.0" iyy="2e-07" iyz="0.0" izz="2e-07"/>
    </inertial>
  </link>
  <joint name="1_4x6_12_joint_x" type="prismatic">
    <origin rpy="0.0 0.0 0.0" xyz="0.04644 0.019335 0.005"/>
    <parent link="1_4x6_base_link"/>
    <child link="1_4x6_12_base2x"/>
    <axis xyz="1 0 0"/>
    <limit effort="100.0" lower="-0.0015" upper="0.0015" velocity="0.5"/>
  </joint>
  <joint name="1_4x6_12_joint_y" type="prismatic">
    <origin rpy="0.0 0.0 0.0" xyz="0.0 0.0 0.0"/>
    <parent link="1_4x6_12_base2x"/>
    <child link="1_4x6_12_x2y"/>
    <axis xyz="0 1 0"/>
    <limit effort="100.0" lower="-0.0015" upper="0.0015" velocity="0.5"/>
  </joint>
  <joint name="1_4x6_12_joint_z" type="prismatic">
    <origin rpy="0.0 0.0 0.0" xyz="0.0 0.0 0.0"/>
    <parent link="1_4x6_12_x2y"/>
    <child link="1_4x6_12_taxel_base_link"/>
    <axis xyz="0 0 1"/>
    <limit effort="100.0" lower="-0.001" upper="0.000" velocity="0.5"/>
  </joint>
  <link name="1_4x6_13_taxel_base_link">
    <visual>
      <geometry>
        <sphere radius="0.001"/>
      </geometry>
      <origin rpy="0 0 0" xyz="0.0 0.0 0.0"/>
      <material name="blue"/>
    </visual>
    <collision>
      <geometry>
        <sphere radius="0.001"/>
      </geometry>
    </collision>
    <inertial>
      <mass value="0.005"/>
      <origin rpy="0 0 0" xyz="0 0 0"/>
      <inertia ixx="2e-07" ixy="0.0" ixz="0.0" iyy="2e-07" iyz="0.0" izz="2e-07"/>
    </inertial>
  </link>
  <link name="1_4x6_13_base2x">
    <visual>
      <geometry>
        <sphere radius="0.0001"/>
      </geometry>
      <origin rpy="0 0 0" xyz="0.010239999999999999 0.012165 0.005"/>
      <material name="blue"/>
    </visual>
    <collision>
      <geometry>
        <sphere radius="0.0001"/>
      </geometry>
    </collision>
    <inertial>
      <mass value="0.005"/>
      <origin rpy="0 0 0" xyz="0 0 0"/>
      <inertia ixx="2e-07" ixy="0.0" ixz="0.0" iyy="2e-07" iyz="0.0" izz="2e-07"/>
    </inertial>
  </link>
  <link name="1_4x6_13_x2y">
    <visual>
      <geometry>
        <sphere radius="0.0001"/>
      </geometry>
      <origin rpy="0 0 0" xyz="0.0 0.0 0.0"/>
      <material name="blue"/>
    </visual>
    <collision>
      <geometry>
        <sphere radius="0.0001"/>
      </geometry>
    </collision>
    <inertial>
      <mass value="0.005"/>
      <origin rpy="0 0 0" xyz="0 0 0"/>
      <inertia ixx="2e-07" ixy="0.0" ixz="0.0" iyy="2e-07" iyz="0.0" izz="2e-07"/>
    </inertial>
  </link>
  <joint name="1_4x6_13_joint_x" type="prismatic">
    <origin rpy="0.0 0.0 0.0" xyz="0.010239999999999999 0.012165 0.005"/>
    <parent link="1_4x6_base_link"/>
    <child link="1_4x6_13_base2x"/>
    <axis xyz="1 0 0"/>
    <limit effort="100.0" lower="-0.0015" upper="0.0015" velocity="0.5"/>
  </joint>
  <joint name="1_4x6_13_joint_y" type="prismatic">
    <origin rpy="0.0 0.0 0.0" xyz="0.0 0.0 0.0"/>
    <parent link="1_4x6_13_base2x"/>
    <child link="1_4x6_13_x2y"/>
    <axis xyz="0 1 0"/>
    <limit effort="100.0" lower="-0.0015" upper="0.0015" velocity="0.5"/>
  </joint>
  <joint name="1_4x6_13_joint_z" type="prismatic">
    <origin rpy="0.0 0.0 0.0" xyz="0.0 0.0 0.0"/>
    <parent link="1_4x6_13_x2y"/>
    <child link="1_4x6_13_taxel_base_link"/>
    <axis xyz="0 0 1"/>
    <limit effort="100.0" lower="-0.001" upper="0.000" velocity="0.5"/>
  </joint>
  <link name="1_4x6_14_taxel_base_link">
    <visual>
      <geometry>
        <sphere radius="0.001"/>
      </geometry>
      <origin rpy="0 0 0" xyz="0.0 0.0 0.0"/>
      <material name="blue"/>
    </visual>
    <collision>
      <geometry>
        <sphere radius="0.001"/>
      </geometry>
    </collision>
    <inertial>
      <mass value="0.005"/>
      <origin rpy="0 0 0" xyz="0 0 0"/>
      <inertia ixx="2e-07" ixy="0.0" ixz="0.0" iyy="2e-07" iyz="0.0" izz="2e-07"/>
    </inertial>
  </link>
  <link name="1_4x6_14_base2x">
    <visual>
      <geometry>
        <sphere radius="0.0001"/>
      </geometry>
      <origin rpy="0 0 0" xyz="0.01748 0.012165 0.005"/>
      <material name="blue"/>
    </visual>
    <collision>
      <geometry>
        <sphere radius="0.0001"/>
      </geometry>
    </collision>
    <inertial>
      <mass value="0.005"/>
      <origin rpy="0 0 0" xyz="0 0 0"/>
      <inertia ixx="2e-07" ixy="0.0" ixz="0.0" iyy="2e-07" iyz="0.0" izz="2e-07"/>
    </inertial>
  </link>
  <link name="1_4x6_14_x2y">
    <visual>
      <geometry>
        <sphere radius="0.0001"/>
      </geometry>
      <origin rpy="0 0 0" xyz="0.0 0.0 0.0"/>
      <material name="blue"/>
    </visual>
    <collision>
      <geometry>
        <sphere radius="0.0001"/>
      </geometry>
    </collision>
    <inertial>
      <mass value="0.005"/>
      <origin rpy="0 0 0" xyz="0 0 0"/>
      <inertia ixx="2e-07" ixy="0.0" ixz="0.0" iyy="2e-07" iyz="0.0" izz="2e-07"/>
    </inertial>
  </link>
  <joint name="1_4x6_14_joint_x" type="prismatic">
    <origin rpy="0.0 0.0 0.0" xyz="0.01748 0.012165 0.005"/>
    <parent link="1_4x6_base_link"/>
    <child link="1_4x6_14_base2x"/>
    <axis xyz="1 0 0"/>
    <limit effort="100.0" lower="-0.0015" upper="0.0015" velocity="0.5"/>
  </joint>
  <joint name="1_4x6_14_joint_y" type="prismatic">
    <origin rpy="0.0 0.0 0.0" xyz="0.0 0.0 0.0"/>
    <parent link="1_4x6_14_base2x"/>
    <child link="1_4x6_14_x2y"/>
    <axis xyz="0 1 0"/>
    <limit effort="100.0" lower="-0.0015" upper="0.0015" velocity="0.5"/>
  </joint>
  <joint name="1_4x6_14_joint_z" type="prismatic">
    <origin rpy="0.0 0.0 0.0" xyz="0.0 0.0 0.0"/>
    <parent link="1_4x6_14_x2y"/>
    <child link="1_4x6_14_taxel_base_link"/>
    <axis xyz="0 0 1"/>
    <limit effort="100.0" lower="-0.001" upper="0.000" velocity="0.5"/>
  </joint>
  <link name="1_4x6_15_taxel_base_link">
    <visual>
      <geometry>
        <sphere radius="0.001"/>
      </geometry>
      <origin rpy="0 0 0" xyz="0.0 0.0 0.0"/>
      <material name="blue"/>
    </visual>
    <collision>
      <geometry>
        <sphere radius="0.001"/>
      </geometry>
    </collision>
    <inertial>
      <mass value="0.005"/>
      <origin rpy="0 0 0" xyz="0 0 0"/>
      <inertia ixx="2e-07" ixy="0.0" ixz="0.0" iyy="2e-07" iyz="0.0" izz="2e-07"/>
    </inertial>
  </link>
  <link name="1_4x6_15_base2x">
    <visual>
      <geometry>
        <sphere radius="0.0001"/>
      </geometry>
      <origin rpy="0 0 0" xyz="0.02472 0.012165 0.005"/>
      <material name="blue"/>
    </visual>
    <collision>
      <geometry>
        <sphere radius="0.0001"/>
      </geometry>
    </collision>
    <inertial>
      <mass value="0.005"/>
      <origin rpy="0 0 0" xyz="0 0 0"/>
      <inertia ixx="2e-07" ixy="0.0" ixz="0.0" iyy="2e-07" iyz="0.0" izz="2e-07"/>
    </inertial>
  </link>
  <link name="1_4x6_15_x2y">
    <visual>
      <geometry>
        <sphere radius="0.0001"/>
      </geometry>
      <origin rpy="0 0 0" xyz="0.0 0.0 0.0"/>
      <material name="blue"/>
    </visual>
    <collision>
      <geometry>
        <sphere radius="0.0001"/>
      </geometry>
    </collision>
    <inertial>
      <mass value="0.005"/>
      <origin rpy="0 0 0" xyz="0 0 0"/>
      <inertia ixx="2e-07" ixy="0.0" ixz="0.0" iyy="2e-07" iyz="0.0" izz="2e-07"/>
    </inertial>
  </link>
  <joint name="1_4x6_15_joint_x" type="prismatic">
    <origin rpy="0.0 0.0 0.0" xyz="0.02472 0.012165 0.005"/>
    <parent link="1_4x6_base_link"/>
    <child link="1_4x6_15_base2x"/>
    <axis xyz="1 0 0"/>
    <limit effort="100.0" lower="-0.0015" upper="0.0015" velocity="0.5"/>
  </joint>
  <joint name="1_4x6_15_joint_y" type="prismatic">
    <origin rpy="0.0 0.0 0.0" xyz="0.0 0.0 0.0"/>
    <parent link="1_4x6_15_base2x"/>
    <child link="1_4x6_15_x2y"/>
    <axis xyz="0 1 0"/>
    <limit effort="100.0" lower="-0.0015" upper="0.0015" velocity="0.5"/>
  </joint>
  <joint name="1_4x6_15_joint_z" type="prismatic">
    <origin rpy="0.0 0.0 0.0" xyz="0.0 0.0 0.0"/>
    <parent link="1_4x6_15_x2y"/>
    <child link="1_4x6_15_taxel_base_link"/>
    <axis xyz="0 0 1"/>
    <limit effort="100.0" lower="-0.001" upper="0.000" velocity="0.5"/>
  </joint>
  <link name="1_4x6_16_taxel_base_link">
    <visual>
      <geometry>
        <sphere radius="0.001"/>
      </geometry>
      <origin rpy="0 0 0" xyz="0.0 0.0 0.0"/>
      <material name="blue"/>
    </visual>
    <collision>
      <geometry>
        <sphere radius="0.001"/>
      </geometry>
    </collision>
    <inertial>
      <mass value="0.005"/>
      <origin rpy="0 0 0" xyz="0 0 0"/>
      <inertia ixx="2e-07" ixy="0.0" ixz="0.0" iyy="2e-07" iyz="0.0" izz="2e-07"/>
    </inertial>
  </link>
  <link name="1_4x6_16_base2x">
    <visual>
      <geometry>
        <sphere radius="0.0001"/>
      </geometry>
      <origin rpy="0 0 0" xyz="0.03196 0.012165 0.005"/>
      <material name="blue"/>
    </visual>
    <collision>
      <geometry>
        <sphere radius="0.0001"/>
      </geometry>
    </collision>
    <inertial>
      <mass value="0.005"/>
      <origin rpy="0 0 0" xyz="0 0 0"/>
      <inertia ixx="2e-07" ixy="0.0" ixz="0.0" iyy="2e-07" iyz="0.0" izz="2e-07"/>
    </inertial>
  </link>
  <link name="1_4x6_16_x2y">
    <visual>
      <geometry>
        <sphere radius="0.0001"/>
      </geometry>
      <origin rpy="0 0 0" xyz="0.0 0.0 0.0"/>
      <material name="blue"/>
    </visual>
    <collision>
      <geometry>
        <sphere radius="0.0001"/>
      </geometry>
    </collision>
    <inertial>
      <mass value="0.005"/>
      <origin rpy="0 0 0" xyz="0 0 0"/>
      <inertia ixx="2e-07" ixy="0.0" ixz="0.0" iyy="2e-07" iyz="0.0" izz="2e-07"/>
    </inertial>
  </link>
  <joint name="1_4x6_16_joint_x" type="prismatic">
    <origin rpy="0.0 0.0 0.0" xyz="0.03196 0.012165 0.005"/>
    <parent link="1_4x6_base_link"/>
    <child link="1_4x6_16_base2x"/>
    <axis xyz="1 0 0"/>
    <limit effort="100.0" lower="-0.0015" upper="0.0015" velocity="0.5"/>
  </joint>
  <joint name="1_4x6_16_joint_y" type="prismatic">
    <origin rpy="0.0 0.0 0.0" xyz="0.0 0.0 0.0"/>
    <parent link="1_4x6_16_base2x"/>
    <child link="1_4x6_16_x2y"/>
    <axis xyz="0 1 0"/>
    <limit effort="100.0" lower="-0.0015" upper="0.0015" velocity="0.5"/>
  </joint>
  <joint name="1_4x6_16_joint_z" type="prismatic">
    <origin rpy="0.0 0.0 0.0" xyz="0.0 0.0 0.0"/>
    <parent link="1_4x6_16_x2y"/>
    <child link="1_4x6_16_taxel_base_link"/>
    <axis xyz="0 0 1"/>
    <limit effort="100.0" lower="-0.001" upper="0.000" velocity="0.5"/>
  </joint>
  <link name="1_4x6_17_taxel_base_link">
    <visual>
      <geometry>
        <sphere radius="0.001"/>
      </geometry>
      <origin rpy="0 0 0" xyz="0.0 0.0 0.0"/>
      <material name="blue"/>
    </visual>
    <collision>
      <geometry>
        <sphere radius="0.001"/>
      </geometry>
    </collision>
    <inertial>
      <mass value="0.005"/>
      <origin rpy="0 0 0" xyz="0 0 0"/>
      <inertia ixx="2e-07" ixy="0.0" ixz="0.0" iyy="2e-07" iyz="0.0" izz="2e-07"/>
    </inertial>
  </link>
  <link name="1_4x6_17_base2x">
    <visual>
      <geometry>
        <sphere radius="0.0001"/>
      </geometry>
      <origin rpy="0 0 0" xyz="0.0392 0.012165 0.005"/>
      <material name="blue"/>
    </visual>
    <collision>
      <geometry>
        <sphere radius="0.0001"/>
      </geometry>
    </collision>
    <inertial>
      <mass value="0.005"/>
      <origin rpy="0 0 0" xyz="0 0 0"/>
      <inertia ixx="2e-07" ixy="0.0" ixz="0.0" iyy="2e-07" iyz="0.0" izz="2e-07"/>
    </inertial>
  </link>
  <link name="1_4x6_17_x2y">
    <visual>
      <geometry>
        <sphere radius="0.0001"/>
      </geometry>
      <origin rpy="0 0 0" xyz="0.0 0.0 0.0"/>
      <material name="blue"/>
    </visual>
    <collision>
      <geometry>
        <sphere radius="0.0001"/>
      </geometry>
    </collision>
    <inertial>
      <mass value="0.005"/>
      <origin rpy="0 0 0" xyz="0 0 0"/>
      <inertia ixx="2e-07" ixy="0.0" ixz="0.0" iyy="2e-07" iyz="0.0" izz="2e-07"/>
    </inertial>
  </link>
  <joint name="1_4x6_17_joint_x" type="prismatic">
    <origin rpy="0.0 0.0 0.0" xyz="0.0392 0.012165 0.005"/>
    <parent link="1_4x6_base_link"/>
    <child link="1_4x6_17_base2x"/>
    <axis xyz="1 0 0"/>
    <limit effort="100.0" lower="-0.0015" upper="0.0015" velocity="0.5"/>
  </joint>
  <joint name="1_4x6_17_joint_y" type="prismatic">
    <origin rpy="0.0 0.0 0.0" xyz="0.0 0.0 0.0"/>
    <parent link="1_4x6_17_base2x"/>
    <child link="1_4x6_17_x2y"/>
    <axis xyz="0 1 0"/>
    <limit effort="100.0" lower="-0.0015" upper="0.0015" velocity="0.5"/>
  </joint>
  <joint name="1_4x6_17_joint_z" type="prismatic">
    <origin rpy="0.0 0.0 0.0" xyz="0.0 0.0 0.0"/>
    <parent link="1_4x6_17_x2y"/>
    <child link="1_4x6_17_taxel_base_link"/>
    <axis xyz="0 0 1"/>
    <limit effort="100.0" lower="-0.001" upper="0.000" velocity="0.5"/>
  </joint>
  <link name="1_4x6_18_taxel_base_link">
    <visual>
      <geometry>
        <sphere radius="0.001"/>
      </geometry>
      <origin rpy="0 0 0" xyz="0.0 0.0 0.0"/>
      <material name="blue"/>
    </visual>
    <collision>
      <geometry>
        <sphere radius="0.001"/>
      </geometry>
    </collision>
    <inertial>
      <mass value="0.005"/>
      <origin rpy="0 0 0" xyz="0 0 0"/>
      <inertia ixx="2e-07" ixy="0.0" ixz="0.0" iyy="2e-07" iyz="0.0" izz="2e-07"/>
    </inertial>
  </link>
  <link name="1_4x6_18_base2x">
    <visual>
      <geometry>
        <sphere radius="0.0001"/>
      </geometry>
      <origin rpy="0 0 0" xyz="0.04644 0.012165 0.005"/>
      <material name="blue"/>
    </visual>
    <collision>
      <geometry>
        <sphere radius="0.0001"/>
      </geometry>
    </collision>
    <inertial>
      <mass value="0.005"/>
      <origin rpy="0 0 0" xyz="0 0 0"/>
      <inertia ixx="2e-07" ixy="0.0" ixz="0.0" iyy="2e-07" iyz="0.0" izz="2e-07"/>
    </inertial>
  </link>
  <link name="1_4x6_18_x2y">
    <visual>
      <geometry>
        <sphere radius="0.0001"/>
      </geometry>
      <origin rpy="0 0 0" xyz="0.0 0.0 0.0"/>
      <material name="blue"/>
    </visual>
    <collision>
      <geometry>
        <sphere radius="0.0001"/>
      </geometry>
    </collision>
    <inertial>
      <mass value="0.005"/>
      <origin rpy="0 0 0" xyz="0 0 0"/>
      <inertia ixx="2e-07" ixy="0.0" ixz="0.0" iyy="2e-07" iyz="0.0" izz="2e-07"/>
    </inertial>
  </link>
  <joint name="1_4x6_18_joint_x" type="prismatic">
    <origin rpy="0.0 0.0 0.0" xyz="0.04644 0.012165 0.005"/>
    <parent link="1_4x6_base_link"/>
    <child link="1_4x6_18_base2x"/>
    <axis xyz="1 0 0"/>
    <limit effort="100.0" lower="-0.0015" upper="0.0015" velocity="0.5"/>
  </joint>
  <joint name="1_4x6_18_joint_y" type="prismatic">
    <origin rpy="0.0 0.0 0.0" xyz="0.0 0.0 0.0"/>
    <parent link="1_4x6_18_base2x"/>
    <child link="1_4x6_18_x2y"/>
    <axis xyz="0 1 0"/>
    <limit effort="100.0" lower="-0.0015" upper="0.0015" velocity="0.5"/>
  </joint>
  <joint name="1_4x6_18_joint_z" type="prismatic">
    <origin rpy="0.0 0.0 0.0" xyz="0.0 0.0 0.0"/>
    <parent link="1_4x6_18_x2y"/>
    <child link="1_4x6_18_taxel_base_link"/>
    <axis xyz="0 0 1"/>
    <limit effort="100.0" lower="-0.001" upper="0.000" velocity="0.5"/>
  </joint>
  <link name="1_4x6_19_taxel_base_link">
    <visual>
      <geometry>
        <sphere radius="0.001"/>
      </geometry>
      <origin rpy="0 0 0" xyz="0.0 0.0 0.0"/>
      <material name="blue"/>
    </visual>
    <collision>
      <geometry>
        <sphere radius="0.001"/>
      </geometry>
    </collision>
    <inertial>
      <mass value="0.005"/>
      <origin rpy="0 0 0" xyz="0 0 0"/>
      <inertia ixx="2e-07" ixy="0.0" ixz="0.0" iyy="2e-07" iyz="0.0" izz="2e-07"/>
    </inertial>
  </link>
  <link name="1_4x6_19_base2x">
    <visual>
      <geometry>
        <sphere radius="0.0001"/>
      </geometry>
      <origin rpy="0 0 0" xyz="0.010239999999999999 0.004995 0.005"/>
      <material name="blue"/>
    </visual>
    <collision>
      <geometry>
        <sphere radius="0.0001"/>
      </geometry>
    </collision>
    <inertial>
      <mass value="0.005"/>
      <origin rpy="0 0 0" xyz="0 0 0"/>
      <inertia ixx="2e-07" ixy="0.0" ixz="0.0" iyy="2e-07" iyz="0.0" izz="2e-07"/>
    </inertial>
  </link>
  <link name="1_4x6_19_x2y">
    <visual>
      <geometry>
        <sphere radius="0.0001"/>
      </geometry>
      <origin rpy="0 0 0" xyz="0.0 0.0 0.0"/>
      <material name="blue"/>
    </visual>
    <collision>
      <geometry>
        <sphere radius="0.0001"/>
      </geometry>
    </collision>
    <inertial>
      <mass value="0.005"/>
      <origin rpy="0 0 0" xyz="0 0 0"/>
      <inertia ixx="2e-07" ixy="0.0" ixz="0.0" iyy="2e-07" iyz="0.0" izz="2e-07"/>
    </inertial>
  </link>
  <joint name="1_4x6_19_joint_x" type="prismatic">
    <origin rpy="0.0 0.0 0.0" xyz="0.010239999999999999 0.004995 0.005"/>
    <parent link="1_4x6_base_link"/>
    <child link="1_4x6_19_base2x"/>
    <axis xyz="1 0 0"/>
    <limit effort="100.0" lower="-0.0015" upper="0.0015" velocity="0.5"/>
  </joint>
  <joint name="1_4x6_19_joint_y" type="prismatic">
    <origin rpy="0.0 0.0 0.0" xyz="0.0 0.0 0.0"/>
    <parent link="1_4x6_19_base2x"/>
    <child link="1_4x6_19_x2y"/>
    <axis xyz="0 1 0"/>
    <limit effort="100.0" lower="-0.0015" upper="0.0015" velocity="0.5"/>
  </joint>
  <joint name="1_4x6_19_joint_z" type="prismatic">
    <origin rpy="0.0 0.0 0.0" xyz="0.0 0.0 0.0"/>
    <parent link="1_4x6_19_x2y"/>
    <child link="1_4x6_19_taxel_base_link"/>
    <axis xyz="0 0 1"/>
    <limit effort="100.0" lower="-0.001" upper="0.000" velocity="0.5"/>
  </joint>
  <link name="1_4x6_20_taxel_base_link">
    <visual>
      <geometry>
        <sphere radius="0.001"/>
      </geometry>
      <origin rpy="0 0 0" xyz="0.0 0.0 0.0"/>
      <material name="blue"/>
    </visual>
    <collision>
      <geometry>
        <sphere radius="0.001"/>
      </geometry>
    </collision>
    <inertial>
      <mass value="0.005"/>
      <origin rpy="0 0 0" xyz="0 0 0"/>
      <inertia ixx="2e-07" ixy="0.0" ixz="0.0" iyy="2e-07" iyz="0.0" izz="2e-07"/>
    </inertial>
  </link>
  <link name="1_4x6_20_base2x">
    <visual>
      <geometry>
        <sphere radius="0.0001"/>
      </geometry>
      <origin rpy="0 0 0" xyz="0.01748 0.004995 0.005"/>
      <material name="blue"/>
    </visual>
    <collision>
      <geometry>
        <sphere radius="0.0001"/>
      </geometry>
    </collision>
    <inertial>
      <mass value="0.005"/>
      <origin rpy="0 0 0" xyz="0 0 0"/>
      <inertia ixx="2e-07" ixy="0.0" ixz="0.0" iyy="2e-07" iyz="0.0" izz="2e-07"/>
    </inertial>
  </link>
  <link name="1_4x6_20_x2y">
    <visual>
      <geometry>
        <sphere radius="0.0001"/>
      </geometry>
      <origin rpy="0 0 0" xyz="0.0 0.0 0.0"/>
      <material name="blue"/>
    </visual>
    <collision>
      <geometry>
        <sphere radius="0.0001"/>
      </geometry>
    </collision>
    <inertial>
      <mass value="0.005"/>
      <origin rpy="0 0 0" xyz="0 0 0"/>
      <inertia ixx="2e-07" ixy="0.0" ixz="0.0" iyy="2e-07" iyz="0.0" izz="2e-07"/>
    </inertial>
  </link>
  <joint name="1_4x6_20_joint_x" type="prismatic">
    <origin rpy="0.0 0.0 0.0" xyz="0.01748 0.004995 0.005"/>
    <parent link="1_4x6_base_link"/>
    <child link="1_4x6_20_base2x"/>
    <axis xyz="1 0 0"/>
    <limit effort="100.0" lower="-0.0015" upper="0.0015" velocity="0.5"/>
  </joint>
  <joint name="1_4x6_20_joint_y" type="prismatic">
    <origin rpy="0.0 0.0 0.0" xyz="0.0 0.0 0.0"/>
    <parent link="1_4x6_20_base2x"/>
    <child link="1_4x6_20_x2y"/>
    <axis xyz="0 1 0"/>
    <limit effort="100.0" lower="-0.0015" upper="0.0015" velocity="0.5"/>
  </joint>
  <joint name="1_4x6_20_joint_z" type="prismatic">
    <origin rpy="0.0 0.0 0.0" xyz="0.0 0.0 0.0"/>
    <parent link="1_4x6_20_x2y"/>
    <child link="1_4x6_20_taxel_base_link"/>
    <axis xyz="0 0 1"/>
    <limit effort="100.0" lower="-0.001" upper="0.000" velocity="0.5"/>
  </joint>
  <link name="1_4x6_21_taxel_base_link">
    <visual>
      <geometry>
        <sphere radius="0.001"/>
      </geometry>
      <origin rpy="0 0 0" xyz="0.0 0.0 0.0"/>
      <material name="blue"/>
    </visual>
    <collision>
      <geometry>
        <sphere radius="0.001"/>
      </geometry>
    </collision>
    <inertial>
      <mass value="0.005"/>
      <origin rpy="0 0 0" xyz="0 0 0"/>
      <inertia ixx="2e-07" ixy="0.0" ixz="0.0" iyy="2e-07" iyz="0.0" izz="2e-07"/>
    </inertial>
  </link>
  <link name="1_4x6_21_base2x">
    <visual>
      <geometry>
        <sphere radius="0.0001"/>
      </geometry>
      <origin rpy="0 0 0" xyz="0.02472 0.004995 0.005"/>
      <material name="blue"/>
    </visual>
    <collision>
      <geometry>
        <sphere radius="0.0001"/>
      </geometry>
    </collision>
    <inertial>
      <mass value="0.005"/>
      <origin rpy="0 0 0" xyz="0 0 0"/>
      <inertia ixx="2e-07" ixy="0.0" ixz="0.0" iyy="2e-07" iyz="0.0" izz="2e-07"/>
    </inertial>
  </link>
  <link name="1_4x6_21_x2y">
    <visual>
      <geometry>
        <sphere radius="0.0001"/>
      </geometry>
      <origin rpy="0 0 0" xyz="0.0 0.0 0.0"/>
      <material name="blue"/>
    </visual>
    <collision>
      <geometry>
        <sphere radius="0.0001"/>
      </geometry>
    </collision>
    <inertial>
      <mass value="0.005"/>
      <origin rpy="0 0 0" xyz="0 0 0"/>
      <inertia ixx="2e-07" ixy="0.0" ixz="0.0" iyy="2e-07" iyz="0.0" izz="2e-07"/>
    </inertial>
  </link>
  <joint name="1_4x6_21_joint_x" type="prismatic">
    <origin rpy="0.0 0.0 0.0" xyz="0.02472 0.004995 0.005"/>
    <parent link="1_4x6_base_link"/>
    <child link="1_4x6_21_base2x"/>
    <axis xyz="1 0 0"/>
    <limit effort="100.0" lower="-0.0015" upper="0.0015" velocity="0.5"/>
  </joint>
  <joint name="1_4x6_21_joint_y" type="prismatic">
    <origin rpy="0.0 0.0 0.0" xyz="0.0 0.0 0.0"/>
    <parent link="1_4x6_21_base2x"/>
    <child link="1_4x6_21_x2y"/>
    <axis xyz="0 1 0"/>
    <limit effort="100.0" lower="-0.0015" upper="0.0015" velocity="0.5"/>
  </joint>
  <joint name="1_4x6_21_joint_z" type="prismatic">
    <origin rpy="0.0 0.0 0.0" xyz="0.0 0.0 0.0"/>
    <parent link="1_4x6_21_x2y"/>
    <child link="1_4x6_21_taxel_base_link"/>
    <axis xyz="0 0 1"/>
    <limit effort="100.0" lower="-0.001" upper="0.000" velocity="0.5"/>
  </joint>
  <link name="1_4x6_22_taxel_base_link">
    <visual>
      <geometry>
        <sphere radius="0.001"/>
      </geometry>
      <origin rpy="0 0 0" xyz="0.0 0.0 0.0"/>
      <material name="blue"/>
    </visual>
    <collision>
      <geometry>
        <sphere radius="0.001"/>
      </geometry>
    </collision>
    <inertial>
      <mass value="0.005"/>
      <origin rpy="0 0 0" xyz="0 0 0"/>
      <inertia ixx="2e-07" ixy="0.0" ixz="0.0" iyy="2e-07" iyz="0.0" izz="2e-07"/>
    </inertial>
  </link>
  <link name="1_4x6_22_base2x">
    <visual>
      <geometry>
        <sphere radius="0.0001"/>
      </geometry>
      <origin rpy="0 0 0" xyz="0.03196 0.004995 0.005"/>
      <material name="blue"/>
    </visual>
    <collision>
      <geometry>
        <sphere radius="0.0001"/>
      </geometry>
    </collision>
    <inertial>
      <mass value="0.005"/>
      <origin rpy="0 0 0" xyz="0 0 0"/>
      <inertia ixx="2e-07" ixy="0.0" ixz="0.0" iyy="2e-07" iyz="0.0" izz="2e-07"/>
    </inertial>
  </link>
  <link name="1_4x6_22_x2y">
    <visual>
      <geometry>
        <sphere radius="0.0001"/>
      </geometry>
      <origin rpy="0 0 0" xyz="0.0 0.0 0.0"/>
      <material name="blue"/>
    </visual>
    <collision>
      <geometry>
        <sphere radius="0.0001"/>
      </geometry>
    </collision>
    <inertial>
      <mass value="0.005"/>
      <origin rpy="0 0 0" xyz="0 0 0"/>
      <inertia ixx="2e-07" ixy="0.0" ixz="0.0" iyy="2e-07" iyz="0.0" izz="2e-07"/>
    </inertial>
  </link>
  <joint name="1_4x6_22_joint_x" type="prismatic">
    <origin rpy="0.0 0.0 0.0" xyz="0.03196 0.004995 0.005"/>
    <parent link="1_4x6_base_link"/>
    <child link="1_4x6_22_base2x"/>
    <axis xyz="1 0 0"/>
    <limit effort="100.0" lower="-0.0015" upper="0.0015" velocity="0.5"/>
  </joint>
  <joint name="1_4x6_22_joint_y" type="prismatic">
    <origin rpy="0.0 0.0 0.0" xyz="0.0 0.0 0.0"/>
    <parent link="1_4x6_22_base2x"/>
    <child link="1_4x6_22_x2y"/>
    <axis xyz="0 1 0"/>
    <limit effort="100.0" lower="-0.0015" upper="0.0015" velocity="0.5"/>
  </joint>
  <joint name="1_4x6_22_joint_z" type="prismatic">
    <origin rpy="0.0 0.0 0.0" xyz="0.0 0.0 0.0"/>
    <parent link="1_4x6_22_x2y"/>
    <child link="1_4x6_22_taxel_base_link"/>
    <axis xyz="0 0 1"/>
    <limit effort="100.0" lower="-0.001" upper="0.000" velocity="0.5"/>
  </joint>
  <link name="1_4x6_23_taxel_base_link">
    <visual>
      <geometry>
        <sphere radius="0.001"/>
      </geometry>
      <origin rpy="0 0 0" xyz="0.0 0.0 0.0"/>
      <material name="blue"/>
    </visual>
    <collision>
      <geometry>
        <sphere radius="0.001"/>
      </geometry>
    </collision>
    <inertial>
      <mass value="0.005"/>
      <origin rpy="0 0 0" xyz="0 0 0"/>
      <inertia ixx="2e-07" ixy="0.0" ixz="0.0" iyy="2e-07" iyz="0.0" izz="2e-07"/>
    </inertial>
  </link>
  <link name="1_4x6_23_base2x">
    <visual>
      <geometry>
        <sphere radius="0.0001"/>
      </geometry>
      <origin rpy="0 0 0" xyz="0.0392 0.004995 0.005"/>
      <material name="blue"/>
    </visual>
    <collision>
      <geometry>
        <sphere radius="0.0001"/>
      </geometry>
    </collision>
    <inertial>
      <mass value="0.005"/>
      <origin rpy="0 0 0" xyz="0 0 0"/>
      <inertia ixx="2e-07" ixy="0.0" ixz="0.0" iyy="2e-07" iyz="0.0" izz="2e-07"/>
    </inertial>
  </link>
  <link name="1_4x6_23_x2y">
    <visual>
      <geometry>
        <sphere radius="0.0001"/>
      </geometry>
      <origin rpy="0 0 0" xyz="0.0 0.0 0.0"/>
      <material name="blue"/>
    </visual>
    <collision>
      <geometry>
        <sphere radius="0.0001"/>
      </geometry>
    </collision>
    <inertial>
      <mass value="0.005"/>
      <origin rpy="0 0 0" xyz="0 0 0"/>
      <inertia ixx="2e-07" ixy="0.0" ixz="0.0" iyy="2e-07" iyz="0.0" izz="2e-07"/>
    </inertial>
  </link>
  <joint name="1_4x6_23_joint_x" type="prismatic">
    <origin rpy="0.0 0.0 0.0" xyz="0.0392 0.004995 0.005"/>
    <parent link="1_4x6_base_link"/>
    <child link="1_4x6_23_base2x"/>
    <axis xyz="1 0 0"/>
    <limit effort="100.0" lower="-0.0015" upper="0.0015" velocity="0.5"/>
  </joint>
  <joint name="1_4x6_23_joint_y" type="prismatic">
    <origin rpy="0.0 0.0 0.0" xyz="0.0 0.0 0.0"/>
    <parent link="1_4x6_23_base2x"/>
    <child link="1_4x6_23_x2y"/>
    <axis xyz="0 1 0"/>
    <limit effort="100.0" lower="-0.0015" upper="0.0015" velocity="0.5"/>
  </joint>
  <joint name="1_4x6_23_joint_z" type="prismatic">
    <origin rpy="0.0 0.0 0.0" xyz="0.0 0.0 0.0"/>
    <parent link="1_4x6_23_x2y"/>
    <child link="1_4x6_23_taxel_base_link"/>
    <axis xyz="0 0 1"/>
    <limit effort="100.0" lower="-0.001" upper="0.000" velocity="0.5"/>
  </joint>
  <link name="1_4x6_24_taxel_base_link">
    <visual>
      <geometry>
        <sphere radius="0.001"/>
      </geometry>
      <origin rpy="0 0 0" xyz="0.0 0.0 0.0"/>
      <material name="blue"/>
    </visual>
    <collision>
      <geometry>
        <sphere radius="0.001"/>
      </geometry>
    </collision>
    <inertial>
      <mass value="0.005"/>
      <origin rpy="0 0 0" xyz="0 0 0"/>
      <inertia ixx="2e-07" ixy="0.0" ixz="0.0" iyy="2e-07" iyz="0.0" izz="2e-07"/>
    </inertial>
  </link>
  <link name="1_4x6_24_base2x">
    <visual>
      <geometry>
        <sphere radius="0.0001"/>
      </geometry>
      <origin rpy="0 0 0" xyz="0.04644 0.004995 0.005"/>
      <material name="blue"/>
    </visual>
    <collision>
      <geometry>
        <sphere radius="0.0001"/>
      </geometry>
    </collision>
    <inertial>
      <mass value="0.005"/>
      <origin rpy="0 0 0" xyz="0 0 0"/>
      <inertia ixx="2e-07" ixy="0.0" ixz="0.0" iyy="2e-07" iyz="0.0" izz="2e-07"/>
    </inertial>
  </link>
  <link name="1_4x6_24_x2y">
    <visual>
      <geometry>
        <sphere radius="0.0001"/>
      </geometry>
      <origin rpy="0 0 0" xyz="0.0 0.0 0.0"/>
      <material name="blue"/>
    </visual>
    <collision>
      <geometry>
        <sphere radius="0.0001"/>
      </geometry>
    </collision>
    <inertial>
      <mass value="0.005"/>
      <origin rpy="0 0 0" xyz="0 0 0"/>
      <inertia ixx="2e-07" ixy="0.0" ixz="0.0" iyy="2e-07" iyz="0.0" izz="2e-07"/>
    </inertial>
  </link>
  <joint name="1_4x6_24_joint_x" type="prismatic">
    <origin rpy="0.0 0.0 0.0" xyz="0.04644 0.004995 0.005"/>
    <parent link="1_4x6_base_link"/>
    <child link="1_4x6_24_base2x"/>
    <axis xyz="1 0 0"/>
    <limit effort="100.0" lower="-0.0015" upper="0.0015" velocity="0.5"/>
  </joint>
  <joint name="1_4x6_24_joint_y" type="prismatic">
    <origin rpy="0.0 0.0 0.0" xyz="0.0 0.0 0.0"/>
    <parent link="1_4x6_24_base2x"/>
    <child link="1_4x6_24_x2y"/>
    <axis xyz="0 1 0"/>
    <limit effort="100.0" lower="-0.0015" upper="0.0015" velocity="0.5"/>
  </joint>
  <joint name="1_4x6_24_joint_z" type="prismatic">
    <origin rpy="0.0 0.0 0.0" xyz="0.0 0.0 0.0"/>
    <parent link="1_4x6_24_x2y"/>
    <child link="1_4x6_24_taxel_base_link"/>
    <axis xyz="0 0 1"/>
    <limit effort="100.0" lower="-0.001" upper="0.000" velocity="0.5"/>
  </joint>
</robot>
