<mujoco model="allegro_fingertip_curved">
  <compiler angle="radian"/>
  <statistic meansize="0.01"/>
  <asset>
    <mesh name="ft_c" file="ft_c.stl"/>
  </asset>
  <worldbody>
    <geom size="0.001"/>
    <geom pos="-0.013 0 0" type="mesh" mesh="ft_c"/>
    <body name="1_aftc_1_base2x" pos="-0.0029 0.0306 0.01254" quat="0.683013 -0.183013 0.683013 0.183013">
      <inertial pos="0 0 0" mass="0.005" diaginertia="1e-06 1e-06 1e-06"/>
      <joint name="j_1_x" pos="0 0 0" axis="1 0 0" type="slide" range="-0.0015 0.0015" actuatorfrcrange="-100 100"/>
      <geom size="0.0001" rgba="0 0 0.8 1"/>
      <body name="1_aftc_1_x2y">
        <inertial pos="0 0 0" mass="0.005" diaginertia="1e-06 1e-06 1e-06"/>
        <joint name="j_1_y" pos="0 0 0" axis="0 1 0" type="slide" range="-0.0015 0.0015" actuatorfrcrange="-100 100"/>
        <geom size="0.0001" rgba="0 0 0.8 1"/>
        <body name="1_aftc_1_taxel_base_link">
          <inertial pos="0 0 0" mass="0.005" diaginertia="1e-06 1e-06 1e-06"/>
          <joint name="j_1_z" pos="0 0 0" axis="0 0 1" type="slide" range="-0.001 0" actuatorfrcrange="-100 100"/>
          <geom size="0.001" rgba="0 0 0.8 1"/>
        </body>
      </body>
    </body>
    <body name="1_aftc_2_base2x" pos="-0.0004 0.0236 0.01254" quat="0.704416 -0.0616284 0.704416 0.0616284">
      <inertial pos="0 0 0" mass="0.005" diaginertia="1e-06 1e-06 1e-06"/>
      <joint name="j_2_x" pos="0 0 0" axis="1 0 0" type="slide" range="-0.0015 0.0015" actuatorfrcrange="-100 100"/>
      <geom size="0.0001" rgba="0 0 0.8 1"/>
      <body name="1_aftc_2_x2y">
        <inertial pos="0 0 0" mass="0.005" diaginertia="1e-06 1e-06 1e-06"/>
        <joint name="j_2_y" pos="0 0 0" axis="0 1 0" type="slide" range="-0.0015 0.0015" actuatorfrcrange="-100 100"/>
        <geom size="0.0001" rgba="0 0 0.8 1"/>
        <body name="1_aftc_2_taxel_base_link">
          <inertial pos="0 0 0" mass="0.005" diaginertia="1e-06 1e-06 1e-06"/>
          <joint name="j_2_z" pos="0 0 0" axis="0 0 1" type="slide" range="-0.001 0" actuatorfrcrange="-100 100"/>
          <geom size="0.001" rgba="0 0 0.8 1"/>
        </body>
      </body>
    </body>
    <body name="1_aftc_3_base2x" pos="0.0008 0.0173 0.01254" quat="0.704416 -0.0616284 0.704416 0.0616284">
      <inertial pos="0 0 0" mass="0.005" diaginertia="1e-06 1e-06 1e-06"/>
      <joint name="j_3_x" pos="0 0 0" axis="1 0 0" type="slide" range="-0.0015 0.0015" actuatorfrcrange="-100 100"/>
      <geom size="0.0001" rgba="0 0 0.8 1"/>
      <body name="1_aftc_3_x2y">
        <inertial pos="0 0 0" mass="0.005" diaginertia="1e-06 1e-06 1e-06"/>
        <joint name="j_3_y" pos="0 0 0" axis="0 1 0" type="slide" range="-0.0015 0.0015" actuatorfrcrange="-100 100"/>
        <geom size="0.0001" rgba="0 0 0.8 1"/>
        <body name="1_aftc_3_taxel_base_link">
          <inertial pos="0 0 0" mass="0.005" diaginertia="1e-06 1e-06 1e-06"/>
          <joint name="j_3_z" pos="0 0 0" axis="0 0 1" type="slide" range="-0.001 0" actuatorfrcrange="-100 100"/>
          <geom size="0.001" rgba="0 0 0.8 1"/>
        </body>
      </body>
    </body>
    <body name="1_aftc_4_base2x" pos="0.0013 0.0103 0.01254" quat="0.707107 0 0.707107 0">
      <inertial pos="0 0 0" mass="0.005" diaginertia="1e-06 1e-06 1e-06"/>
      <joint name="j_4_x" pos="0 0 0" axis="1 0 0" type="slide" range="-0.0015 0.0015" actuatorfrcrange="-100 100"/>
      <geom size="0.0001" rgba="0 0 0.8 1"/>
      <body name="1_aftc_4_x2y">
        <inertial pos="0 0 0" mass="0.005" diaginertia="1e-06 1e-06 1e-06"/>
        <joint name="j_4_y" pos="0 0 0" axis="0 1 0" type="slide" range="-0.0015 0.0015" actuatorfrcrange="-100 100"/>
        <geom size="0.0001" rgba="0 0 0.8 1"/>
        <body name="1_aftc_4_taxel_base_link">
          <inertial pos="0 0 0" mass="0.005" diaginertia="1e-06 1e-06 1e-06"/>
          <joint name="j_4_z" pos="0 0 0" axis="0 0 1" type="slide" range="-0.001 0" actuatorfrcrange="-100 100"/>
          <geom size="0.001" rgba="0 0 0.8 1"/>
        </body>
      </body>
    </body>
    <body name="1_aftc_5_base2x" pos="0.0013 0.0038 0.01254" quat="0.707107 0 0.707107 0">
      <inertial pos="0 0 0" mass="0.005" diaginertia="1e-06 1e-06 1e-06"/>
      <joint name="j_5_x" pos="0 0 0" axis="1 0 0" type="slide" range="-0.0015 0.0015" actuatorfrcrange="-100 100"/>
      <geom size="0.0001" rgba="0 0 0.8 1"/>
      <body name="1_aftc_5_x2y">
        <inertial pos="0 0 0" mass="0.005" diaginertia="1e-06 1e-06 1e-06"/>
        <joint name="j_5_y" pos="0 0 0" axis="0 1 0" type="slide" range="-0.0015 0.0015" actuatorfrcrange="-100 100"/>
        <geom size="0.0001" rgba="0 0 0.8 1"/>
        <body name="1_aftc_5_taxel_base_link">
          <inertial pos="0 0 0" mass="0.005" diaginertia="1e-06 1e-06 1e-06"/>
          <joint name="j_5_z" pos="0 0 0" axis="0 0 1" type="slide" range="-0.001 0" actuatorfrcrange="-100 100"/>
          <geom size="0.001" rgba="0 0 0.8 1"/>
        </body>
      </body>
    </body>
    <body name="1_aftc_6_base2x" pos="-0.0032 0.023 0.02" quat="0.902859 -0.0368336 0.42101 0.0789899">
      <inertial pos="0 0 0" mass="0.005" diaginertia="1e-06 1e-06 1e-06"/>
      <joint name="j_6_x" pos="0 0 0" axis="1 0 0" type="slide" range="-0.0015 0.0015" actuatorfrcrange="-100 100"/>
      <geom size="0.0001" rgba="0 0 0.8 1"/>
      <body name="1_aftc_6_x2y">
        <inertial pos="0 0 0" mass="0.005" diaginertia="1e-06 1e-06 1e-06"/>
        <joint name="j_6_y" pos="0 0 0" axis="0 1 0" type="slide" range="-0.0015 0.0015" actuatorfrcrange="-100 100"/>
        <geom size="0.0001" rgba="0 0 0.8 1"/>
        <body name="1_aftc_6_taxel_base_link">
          <inertial pos="0 0 0" mass="0.005" diaginertia="1e-06 1e-06 1e-06"/>
          <joint name="j_6_z" pos="0 0 0" axis="0 0 1" type="slide" range="-0.001 0" actuatorfrcrange="-100 100"/>
          <geom size="0.001" rgba="0 0 0.8 1"/>
        </body>
      </body>
    </body>
    <body name="1_aftc_7_base2x" pos="-0.002 0.0167 0.02" quat="0.902859 -0.0368336 0.42101 0.0789899">
      <inertial pos="0 0 0" mass="0.005" diaginertia="1e-06 1e-06 1e-06"/>
      <joint name="j_7_x" pos="0 0 0" axis="1 0 0" type="slide" range="-0.0015 0.0015" actuatorfrcrange="-100 100"/>
      <geom size="0.0001" rgba="0 0 0.8 1"/>
      <body name="1_aftc_7_x2y">
        <inertial pos="0 0 0" mass="0.005" diaginertia="1e-06 1e-06 1e-06"/>
        <joint name="j_7_y" pos="0 0 0" axis="0 1 0" type="slide" range="-0.0015 0.0015" actuatorfrcrange="-100 100"/>
        <geom size="0.0001" rgba="0 0 0.8 1"/>
        <body name="1_aftc_7_taxel_base_link">
          <inertial pos="0 0 0" mass="0.005" diaginertia="1e-06 1e-06 1e-06"/>
          <joint name="j_7_z" pos="0 0 0" axis="0 0 1" type="slide" range="-0.001 0" actuatorfrcrange="-100 100"/>
          <geom size="0.001" rgba="0 0 0.8 1"/>
        </body>
      </body>
    </body>
    <body name="1_aftc_8_base2x" pos="-0.0015 0.0103 0.02" quat="0.906308 0 0.422618 0">
      <inertial pos="0 0 0" mass="0.005" diaginertia="1e-06 1e-06 1e-06"/>
      <joint name="j_8_x" pos="0 0 0" axis="1 0 0" type="slide" range="-0.0015 0.0015" actuatorfrcrange="-100 100"/>
      <geom size="0.0001" rgba="0 0 0.8 1"/>
      <body name="1_aftc_8_x2y">
        <inertial pos="0 0 0" mass="0.005" diaginertia="1e-06 1e-06 1e-06"/>
        <joint name="j_8_y" pos="0 0 0" axis="0 1 0" type="slide" range="-0.0015 0.0015" actuatorfrcrange="-100 100"/>
        <geom size="0.0001" rgba="0 0 0.8 1"/>
        <body name="1_aftc_8_taxel_base_link">
          <inertial pos="0 0 0" mass="0.005" diaginertia="1e-06 1e-06 1e-06"/>
          <joint name="j_8_z" pos="0 0 0" axis="0 0 1" type="slide" range="-0.001 0" actuatorfrcrange="-100 100"/>
          <geom size="0.001" rgba="0 0 0.8 1"/>
        </body>
      </body>
    </body>
    <body name="1_aftc_9_base2x" pos="-0.0015 0.0038 0.02" quat="0.906308 0 0.422618 0">
      <inertial pos="0 0 0" mass="0.005" diaginertia="1e-06 1e-06 1e-06"/>
      <joint name="j_9_x" pos="0 0 0" axis="1 0 0" type="slide" range="-0.0015 0.0015" actuatorfrcrange="-100 100"/>
      <geom size="0.0001" rgba="0 0 0.8 1"/>
      <body name="1_aftc_9_x2y">
        <inertial pos="0 0 0" mass="0.005" diaginertia="1e-06 1e-06 1e-06"/>
        <joint name="j_9_y" pos="0 0 0" axis="0 1 0" type="slide" range="-0.0015 0.0015" actuatorfrcrange="-100 100"/>
        <geom size="0.0001" rgba="0 0 0.8 1"/>
        <body name="1_aftc_9_taxel_base_link">
          <inertial pos="0 0 0" mass="0.005" diaginertia="1e-06 1e-06 1e-06"/>
          <joint name="j_9_z" pos="0 0 0" axis="0 0 1" type="slide" range="-0.001 0" actuatorfrcrange="-100 100"/>
          <geom size="0.001" rgba="0 0 0.8 1"/>
        </body>
      </body>
    </body>
    <body name="1_aftc_10_base2x" pos="-0.0093 0.0338 0.0173" quat="0.884447 -0.393781 0.228734 0.101839">
      <inertial pos="0 0 0" mass="0.005" diaginertia="1e-06 1e-06 1e-06"/>
      <joint name="j_10_x" pos="0 0 0" axis="1 0 0" type="slide" range="-0.0015 0.0015" actuatorfrcrange="-100 100"/>
      <geom size="0.0001" rgba="0 0 0.8 1"/>
      <body name="1_aftc_10_x2y">
        <inertial pos="0 0 0" mass="0.005" diaginertia="1e-06 1e-06 1e-06"/>
        <joint name="j_10_y" pos="0 0 0" axis="0 1 0" type="slide" range="-0.0015 0.0015" actuatorfrcrange="-100 100"/>
        <geom size="0.0001" rgba="0 0 0.8 1"/>
        <body name="1_aftc_10_taxel_base_link">
          <inertial pos="0 0 0" mass="0.005" diaginertia="1e-06 1e-06 1e-06"/>
          <joint name="j_10_z" pos="0 0 0" axis="0 0 1" type="slide" range="-0.001 0" actuatorfrcrange="-100 100"/>
          <geom size="0.001" rgba="0 0 0.8 1"/>
        </body>
      </body>
    </body>
    <body name="1_aftc_11_base2x" pos="-0.0091 0.0296 0.02155" quat="0.938933 -0.260389 0.21677 0.0601156">
      <inertial pos="0 0 0" mass="0.005" diaginertia="1e-06 1e-06 1e-06"/>
      <joint name="j_11_x" pos="0 0 0" axis="1 0 0" type="slide" range="-0.0015 0.0015" actuatorfrcrange="-100 100"/>
      <geom size="0.0001" rgba="0 0 0.8 1"/>
      <body name="1_aftc_11_x2y">
        <inertial pos="0 0 0" mass="0.005" diaginertia="1e-06 1e-06 1e-06"/>
        <joint name="j_11_y" pos="0 0 0" axis="0 1 0" type="slide" range="-0.0015 0.0015" actuatorfrcrange="-100 100"/>
        <geom size="0.0001" rgba="0 0 0.8 1"/>
        <body name="1_aftc_11_taxel_base_link">
          <inertial pos="0 0 0" mass="0.005" diaginertia="1e-06 1e-06 1e-06"/>
          <joint name="j_11_z" pos="0 0 0" axis="0 0 1" type="slide" range="-0.001 0" actuatorfrcrange="-100 100"/>
          <geom size="0.001" rgba="0 0 0.8 1"/>
        </body>
      </body>
    </body>
    <body name="1_aftc_12_base2x" pos="-0.0091 0.023 0.02444" quat="0.977892 -0.0855544 0.190083 0.0166301">
      <inertial pos="0 0 0" mass="0.005" diaginertia="1e-06 1e-06 1e-06"/>
      <joint name="j_12_x" pos="0 0 0" axis="1 0 0" type="slide" range="-0.0015 0.0015" actuatorfrcrange="-100 100"/>
      <geom size="0.0001" rgba="0 0 0.8 1"/>
      <body name="1_aftc_12_x2y">
        <inertial pos="0 0 0" mass="0.005" diaginertia="1e-06 1e-06 1e-06"/>
        <joint name="j_12_y" pos="0 0 0" axis="0 1 0" type="slide" range="-0.0015 0.0015" actuatorfrcrange="-100 100"/>
        <geom size="0.0001" rgba="0 0 0.8 1"/>
        <body name="1_aftc_12_taxel_base_link">
          <inertial pos="0 0 0" mass="0.005" diaginertia="1e-06 1e-06 1e-06"/>
          <joint name="j_12_z" pos="0 0 0" axis="0 0 1" type="slide" range="-0.001 0" actuatorfrcrange="-100 100"/>
          <geom size="0.001" rgba="0 0 0.8 1"/>
        </body>
      </body>
    </body>
    <body name="1_aftc_13_base2x" pos="-0.0091 0.0169 0.02544" quat="0.979513 -0.0856963 0.181542 0.0158829">
      <inertial pos="0 0 0" mass="0.005" diaginertia="1e-06 1e-06 1e-06"/>
      <joint name="j_13_x" pos="0 0 0" axis="1 0 0" type="slide" range="-0.0015 0.0015" actuatorfrcrange="-100 100"/>
      <geom size="0.0001" rgba="0 0 0.8 1"/>
      <body name="1_aftc_13_x2y">
        <inertial pos="0 0 0" mass="0.005" diaginertia="1e-06 1e-06 1e-06"/>
        <joint name="j_13_y" pos="0 0 0" axis="0 1 0" type="slide" range="-0.0015 0.0015" actuatorfrcrange="-100 100"/>
        <geom size="0.0001" rgba="0 0 0.8 1"/>
        <body name="1_aftc_13_taxel_base_link">
          <inertial pos="0 0 0" mass="0.005" diaginertia="1e-06 1e-06 1e-06"/>
          <joint name="j_13_z" pos="0 0 0" axis="0 0 1" type="slide" range="-0.001 0" actuatorfrcrange="-100 100"/>
          <geom size="0.001" rgba="0 0 0.8 1"/>
        </body>
      </body>
    </body>
    <body name="1_aftc_14_base2x" pos="-0.0091 0.0103 0.02574" quat="0.987688 0 0.156434 0">
      <inertial pos="0 0 0" mass="0.005" diaginertia="1e-06 1e-06 1e-06"/>
      <joint name="j_14_x" pos="0 0 0" axis="1 0 0" type="slide" range="-0.0015 0.0015" actuatorfrcrange="-100 100"/>
      <geom size="0.0001" rgba="0 0 0.8 1"/>
      <body name="1_aftc_14_x2y">
        <inertial pos="0 0 0" mass="0.005" diaginertia="1e-06 1e-06 1e-06"/>
        <joint name="j_14_y" pos="0 0 0" axis="0 1 0" type="slide" range="-0.0015 0.0015" actuatorfrcrange="-100 100"/>
        <geom size="0.0001" rgba="0 0 0.8 1"/>
        <body name="1_aftc_14_taxel_base_link">
          <inertial pos="0 0 0" mass="0.005" diaginertia="1e-06 1e-06 1e-06"/>
          <joint name="j_14_z" pos="0 0 0" axis="0 0 1" type="slide" range="-0.001 0" actuatorfrcrange="-100 100"/>
          <geom size="0.001" rgba="0 0 0.8 1"/>
        </body>
      </body>
    </body>
    <body name="1_aftc_15_base2x" pos="-0.0091 0.0038 0.02574" quat="0.987688 0 0.156434 0">
      <inertial pos="0 0 0" mass="0.005" diaginertia="1e-06 1e-06 1e-06"/>
      <joint name="j_15_x" pos="0 0 0" axis="1 0 0" type="slide" range="-0.0015 0.0015" actuatorfrcrange="-100 100"/>
      <geom size="0.0001" rgba="0 0 0.8 1"/>
      <body name="1_aftc_15_x2y">
        <inertial pos="0 0 0" mass="0.005" diaginertia="1e-06 1e-06 1e-06"/>
        <joint name="j_15_y" pos="0 0 0" axis="0 1 0" type="slide" range="-0.0015 0.0015" actuatorfrcrange="-100 100"/>
        <geom size="0.0001" rgba="0 0 0.8 1"/>
        <body name="1_aftc_15_taxel_base_link">
          <inertial pos="0 0 0" mass="0.005" diaginertia="1e-06 1e-06 1e-06"/>
          <joint name="j_15_z" pos="0 0 0" axis="0 0 1" type="slide" range="-0.001 0" actuatorfrcrange="-100 100"/>
          <geom size="0.001" rgba="0 0 0.8 1"/>
        </body>
      </body>
    </body>
    <body name="1_aftc_16_base2x" pos="-0.0167 0.0338 0.0173" quat="0.884447 -0.393781 -0.228734 -0.101839">
      <inertial pos="0 0 0" mass="0.005" diaginertia="1e-06 1e-06 1e-06"/>
      <joint name="j_16_x" pos="0 0 0" axis="1 0 0" type="slide" range="-0.0015 0.0015" actuatorfrcrange="-100 100"/>
      <geom size="0.0001" rgba="0 0 0.8 1"/>
      <body name="1_aftc_16_x2y">
        <inertial pos="0 0 0" mass="0.005" diaginertia="1e-06 1e-06 1e-06"/>
        <joint name="j_16_y" pos="0 0 0" axis="0 1 0" type="slide" range="-0.0015 0.0015" actuatorfrcrange="-100 100"/>
        <geom size="0.0001" rgba="0 0 0.8 1"/>
        <body name="1_aftc_16_taxel_base_link">
          <inertial pos="0 0 0" mass="0.005" diaginertia="1e-06 1e-06 1e-06"/>
          <joint name="j_16_z" pos="0 0 0" axis="0 0 1" type="slide" range="-0.001 0" actuatorfrcrange="-100 100"/>
          <geom size="0.001" rgba="0 0 0.8 1"/>
        </body>
      </body>
    </body>
    <body name="1_aftc_17_base2x" pos="-0.0169 0.0296 0.02155" quat="0.938933 -0.260389 -0.21677 -0.0601156">
      <inertial pos="0 0 0" mass="0.005" diaginertia="1e-06 1e-06 1e-06"/>
      <joint name="j_17_x" pos="0 0 0" axis="1 0 0" type="slide" range="-0.0015 0.0015" actuatorfrcrange="-100 100"/>
      <geom size="0.0001" rgba="0 0 0.8 1"/>
      <body name="1_aftc_17_x2y">
        <inertial pos="0 0 0" mass="0.005" diaginertia="1e-06 1e-06 1e-06"/>
        <joint name="j_17_y" pos="0 0 0" axis="0 1 0" type="slide" range="-0.0015 0.0015" actuatorfrcrange="-100 100"/>
        <geom size="0.0001" rgba="0 0 0.8 1"/>
        <body name="1_aftc_17_taxel_base_link">
          <inertial pos="0 0 0" mass="0.005" diaginertia="1e-06 1e-06 1e-06"/>
          <joint name="j_17_z" pos="0 0 0" axis="0 0 1" type="slide" range="-0.001 0" actuatorfrcrange="-100 100"/>
          <geom size="0.001" rgba="0 0 0.8 1"/>
        </body>
      </body>
    </body>
    <body name="1_aftc_18_base2x" pos="-0.0169 0.023 0.02444" quat="0.977892 -0.0855544 -0.190083 -0.0166301">
      <inertial pos="0 0 0" mass="0.005" diaginertia="1e-06 1e-06 1e-06"/>
      <joint name="j_18_x" pos="0 0 0" axis="1 0 0" type="slide" range="-0.0015 0.0015" actuatorfrcrange="-100 100"/>
      <geom size="0.0001" rgba="0 0 0.8 1"/>
      <body name="1_aftc_18_x2y">
        <inertial pos="0 0 0" mass="0.005" diaginertia="1e-06 1e-06 1e-06"/>
        <joint name="j_18_y" pos="0 0 0" axis="0 1 0" type="slide" range="-0.0015 0.0015" actuatorfrcrange="-100 100"/>
        <geom size="0.0001" rgba="0 0 0.8 1"/>
        <body name="1_aftc_18_taxel_base_link">
          <inertial pos="0 0 0" mass="0.005" diaginertia="1e-06 1e-06 1e-06"/>
          <joint name="j_18_z" pos="0 0 0" axis="0 0 1" type="slide" range="-0.001 0" actuatorfrcrange="-100 100"/>
          <geom size="0.001" rgba="0 0 0.8 1"/>
        </body>
      </body>
    </body>
    <body name="1_aftc_19_base2x" pos="-0.0169 0.0169 0.02544" quat="0.979513 -0.0856963 -0.181542 -0.0158829">
      <inertial pos="0 0 0" mass="0.005" diaginertia="1e-06 1e-06 1e-06"/>
      <joint name="j_19_x" pos="0 0 0" axis="1 0 0" type="slide" range="-0.0015 0.0015" actuatorfrcrange="-100 100"/>
      <geom size="0.0001" rgba="0 0 0.8 1"/>
      <body name="1_aftc_19_x2y">
        <inertial pos="0 0 0" mass="0.005" diaginertia="1e-06 1e-06 1e-06"/>
        <joint name="j_19_y" pos="0 0 0" axis="0 1 0" type="slide" range="-0.0015 0.0015" actuatorfrcrange="-100 100"/>
        <geom size="0.0001" rgba="0 0 0.8 1"/>
        <body name="1_aftc_19_taxel_base_link">
          <inertial pos="0 0 0" mass="0.005" diaginertia="1e-06 1e-06 1e-06"/>
          <joint name="j_19_z" pos="0 0 0" axis="0 0 1" type="slide" range="-0.001 0" actuatorfrcrange="-100 100"/>
          <geom size="0.001" rgba="0 0 0.8 1"/>
        </body>
      </body>
    </body>
    <body name="1_aftc_20_base2x" pos="-0.0169 0.0103 0.02574" quat="0.987688 0 -0.156434 0">
      <inertial pos="0 0 0" mass="0.005" diaginertia="1e-06 1e-06 1e-06"/>
      <joint name="j_20_x" pos="0 0 0" axis="1 0 0" type="slide" range="-0.0015 0.0015" actuatorfrcrange="-100 100"/>
      <geom size="0.0001" rgba="0 0 0.8 1"/>
      <body name="1_aftc_20_x2y">
        <inertial pos="0 0 0" mass="0.005" diaginertia="1e-06 1e-06 1e-06"/>
        <joint name="j_20_y" pos="0 0 0" axis="0 1 0" type="slide" range="-0.0015 0.0015" actuatorfrcrange="-100 100"/>
        <geom size="0.0001" rgba="0 0 0.8 1"/>
        <body name="1_aftc_20_taxel_base_link">
          <inertial pos="0 0 0" mass="0.005" diaginertia="1e-06 1e-06 1e-06"/>
          <joint name="j_20_z" pos="0 0 0" axis="0 0 1" type="slide" range="-0.001 0" actuatorfrcrange="-100 100"/>
          <geom size="0.001" rgba="0 0 0.8 1"/>
        </body>
      </body>
    </body>
    <body name="1_aftc_21_base2x" pos="-0.0169 0.0038 0.02574" quat="0.987688 0 -0.156434 0">
      <inertial pos="0 0 0" mass="0.005" diaginertia="1e-06 1e-06 1e-06"/>
      <joint name="j_21_x" pos="0 0 0" axis="1 0 0" type="slide" range="-0.0015 0.0015" actuatorfrcrange="-100 100"/>
      <geom size="0.0001" rgba="0 0 0.8 1"/>
      <body name="1_aftc_21_x2y">
        <inertial pos="0 0 0" mass="0.005" diaginertia="1e-06 1e-06 1e-06"/>
        <joint name="j_21_y" pos="0 0 0" axis="0 1 0" type="slide" range="-0.0015 0.0015" actuatorfrcrange="-100 100"/>
        <geom size="0.0001" rgba="0 0 0.8 1"/>
        <body name="1_aftc_21_taxel_base_link">
          <inertial pos="0 0 0" mass="0.005" diaginertia="1e-06 1e-06 1e-06"/>
          <joint name="j_21_z" pos="0 0 0" axis="0 0 1" type="slide" range="-0.001 0" actuatorfrcrange="-100 100"/>
          <geom size="0.001" rgba="0 0 0.8 1"/>
        </body>
      </body>
    </body>
    <body name="1_aftc_22_base2x" pos="-0.0228 0.023 0.02" quat="0.902859 -0.0368336 -0.42101 -0.0789899">
      <inertial pos="0 0 0" mass="0.005" diaginertia="1e-06 1e-06 1e-06"/>
      <joint name="j_22_x" pos="0 0 0" axis="1 0 0" type="slide" range="-0.0015 0.0015" actuatorfrcrange="-100 100"/>
      <geom size="0.0001" rgba="0 0 0.8 1"/>
      <body name="1_aftc_22_x2y">
        <inertial pos="0 0 0" mass="0.005" diaginertia="1e-06 1e-06 1e-06"/>
        <joint name="j_22_y" pos="0 0 0" axis="0 1 0" type="slide" range="-0.0015 0.0015" actuatorfrcrange="-100 100"/>
        <geom size="0.0001" rgba="0 0 0.8 1"/>
        <body name="1_aftc_22_taxel_base_link">
          <inertial pos="0 0 0" mass="0.005" diaginertia="1e-06 1e-06 1e-06"/>
          <joint name="j_22_z" pos="0 0 0" axis="0 0 1" type="slide" range="-0.001 0" actuatorfrcrange="-100 100"/>
          <geom size="0.001" rgba="0 0 0.8 1"/>
        </body>
      </body>
    </body>
    <body name="1_aftc_23_base2x" pos="-0.024 0.0167 0.02" quat="0.902859 -0.0368336 -0.42101 -0.0789899">
      <inertial pos="0 0 0" mass="0.005" diaginertia="1e-06 1e-06 1e-06"/>
      <joint name="j_23_x" pos="0 0 0" axis="1 0 0" type="slide" range="-0.0015 0.0015" actuatorfrcrange="-100 100"/>
      <geom size="0.0001" rgba="0 0 0.8 1"/>
      <body name="1_aftc_23_x2y">
        <inertial pos="0 0 0" mass="0.005" diaginertia="1e-06 1e-06 1e-06"/>
        <joint name="j_23_y" pos="0 0 0" axis="0 1 0" type="slide" range="-0.0015 0.0015" actuatorfrcrange="-100 100"/>
        <geom size="0.0001" rgba="0 0 0.8 1"/>
        <body name="1_aftc_23_taxel_base_link">
          <inertial pos="0 0 0" mass="0.005" diaginertia="1e-06 1e-06 1e-06"/>
          <joint name="j_23_z" pos="0 0 0" axis="0 0 1" type="slide" range="-0.001 0" actuatorfrcrange="-100 100"/>
          <geom size="0.001" rgba="0 0 0.8 1"/>
        </body>
      </body>
    </body>
    <body name="1_aftc_24_base2x" pos="-0.0245 0.0103 0.02" quat="0.906308 0 -0.422618 0">
      <inertial pos="0 0 0" mass="0.005" diaginertia="1e-06 1e-06 1e-06"/>
      <joint name="j_24_x" pos="0 0 0" axis="1 0 0" type="slide" range="-0.0015 0.0015" actuatorfrcrange="-100 100"/>
      <geom size="0.0001" rgba="0 0 0.8 1"/>
      <body name="1_aftc_24_x2y">
        <inertial pos="0 0 0" mass="0.005" diaginertia="1e-06 1e-06 1e-06"/>
        <joint name="j_24_y" pos="0 0 0" axis="0 1 0" type="slide" range="-0.0015 0.0015" actuatorfrcrange="-100 100"/>
        <geom size="0.0001" rgba="0 0 0.8 1"/>
        <body name="1_aftc_24_taxel_base_link">
          <inertial pos="0 0 0" mass="0.005" diaginertia="1e-06 1e-06 1e-06"/>
          <joint name="j_24_z" pos="0 0 0" axis="0 0 1" type="slide" range="-0.001 0" actuatorfrcrange="-100 100"/>
          <geom size="0.001" rgba="0 0 0.8 1"/>
        </body>
      </body>
    </body>
    <body name="1_aftc_25_base2x" pos="-0.0245 0.0038 0.02" quat="0.906308 0 -0.422618 0">
      <inertial pos="0 0 0" mass="0.005" diaginertia="1e-06 1e-06 1e-06"/>
      <joint name="j_25_x" pos="0 0 0" axis="1 0 0" type="slide" range="-0.0015 0.0015" actuatorfrcrange="-100 100"/>
      <geom size="0.0001" rgba="0 0 0.8 1"/>
      <body name="1_aftc_25_x2y">
        <inertial pos="0 0 0" mass="0.005" diaginertia="1e-06 1e-06 1e-06"/>
        <joint name="j_25_y" pos="0 0 0" axis="0 1 0" type="slide" range="-0.0015 0.0015" actuatorfrcrange="-100 100"/>
        <geom size="0.0001" rgba="0 0 0.8 1"/>
        <body name="1_aftc_25_taxel_base_link">
          <inertial pos="0 0 0" mass="0.005" diaginertia="1e-06 1e-06 1e-06"/>
          <joint name="j_25_z" pos="0 0 0" axis="0 0 1" type="slide" range="-0.001 0" actuatorfrcrange="-100 100"/>
          <geom size="0.001" rgba="0 0 0.8 1"/>
        </body>
      </body>
    </body>
    <body name="1_aftc_26_base2x" pos="-0.0231 0.0306 0.01254" quat="0.683013 -0.183013 -0.683013 -0.183013">
      <inertial pos="0 0 0" mass="0.005" diaginertia="1e-06 1e-06 1e-06"/>
      <joint name="j_26_x" pos="0 0 0" axis="1 0 0" type="slide" range="-0.0015 0.0015" actuatorfrcrange="-100 100"/>
      <geom size="0.0001" rgba="0 0 0.8 1"/>
      <body name="1_aftc_26_x2y">
        <inertial pos="0 0 0" mass="0.005" diaginertia="1e-06 1e-06 1e-06"/>
        <joint name="j_26_y" pos="0 0 0" axis="0 1 0" type="slide" range="-0.0015 0.0015" actuatorfrcrange="-100 100"/>
        <geom size="0.0001" rgba="0 0 0.8 1"/>
        <body name="1_aftc_26_taxel_base_link">
          <inertial pos="0 0 0" mass="0.005" diaginertia="1e-06 1e-06 1e-06"/>
          <joint name="j_26_z" pos="0 0 0" axis="0 0 1" type="slide" range="-0.001 0" actuatorfrcrange="-100 100"/>
          <geom size="0.001" rgba="0 0 0.8 1"/>
        </body>
      </body>
    </body>
    <body name="1_aftc_27_base2x" pos="-0.0256 0.0236 0.01254" quat="0.704416 -0.0616284 -0.704416 -0.0616284">
      <inertial pos="0 0 0" mass="0.005" diaginertia="1e-06 1e-06 1e-06"/>
      <joint name="j_27_x" pos="0 0 0" axis="1 0 0" type="slide" range="-0.0015 0.0015" actuatorfrcrange="-100 100"/>
      <geom size="0.0001" rgba="0 0 0.8 1"/>
      <body name="1_aftc_27_x2y">
        <inertial pos="0 0 0" mass="0.005" diaginertia="1e-06 1e-06 1e-06"/>
        <joint name="j_27_y" pos="0 0 0" axis="0 1 0" type="slide" range="-0.0015 0.0015" actuatorfrcrange="-100 100"/>
        <geom size="0.0001" rgba="0 0 0.8 1"/>
        <body name="1_aftc_27_taxel_base_link">
          <inertial pos="0 0 0" mass="0.005" diaginertia="1e-06 1e-06 1e-06"/>
          <joint name="j_27_z" pos="0 0 0" axis="0 0 1" type="slide" range="-0.001 0" actuatorfrcrange="-100 100"/>
          <geom size="0.001" rgba="0 0 0.8 1"/>
        </body>
      </body>
    </body>
    <body name="1_aftc_28_base2x" pos="-0.0268 0.0173 0.01254" quat="0.704416 -0.0616284 -0.704416 -0.0616284">
      <inertial pos="0 0 0" mass="0.005" diaginertia="1e-06 1e-06 1e-06"/>
      <joint name="j_28_x" pos="0 0 0" axis="1 0 0" type="slide" range="-0.0015 0.0015" actuatorfrcrange="-100 100"/>
      <geom size="0.0001" rgba="0 0 0.8 1"/>
      <body name="1_aftc_28_x2y">
        <inertial pos="0 0 0" mass="0.005" diaginertia="1e-06 1e-06 1e-06"/>
        <joint name="j_28_y" pos="0 0 0" axis="0 1 0" type="slide" range="-0.0015 0.0015" actuatorfrcrange="-100 100"/>
        <geom size="0.0001" rgba="0 0 0.8 1"/>
        <body name="1_aftc_28_taxel_base_link">
          <inertial pos="0 0 0" mass="0.005" diaginertia="1e-06 1e-06 1e-06"/>
          <joint name="j_28_z" pos="0 0 0" axis="0 0 1" type="slide" range="-0.001 0" actuatorfrcrange="-100 100"/>
          <geom size="0.001" rgba="0 0 0.8 1"/>
        </body>
      </body>
    </body>
    <body name="1_aftc_29_base2x" pos="-0.0273 0.0103 0.01254" quat="0.707107 0 -0.707107 0">
      <inertial pos="0 0 0" mass="0.005" diaginertia="1e-06 1e-06 1e-06"/>
      <joint name="j_29_x" pos="0 0 0" axis="1 0 0" type="slide" range="-0.0015 0.0015" actuatorfrcrange="-100 100"/>
      <geom size="0.0001" rgba="0 0 0.8 1"/>
      <body name="1_aftc_29_x2y">
        <inertial pos="0 0 0" mass="0.005" diaginertia="1e-06 1e-06 1e-06"/>
        <joint name="j_29_y" pos="0 0 0" axis="0 1 0" type="slide" range="-0.0015 0.0015" actuatorfrcrange="-100 100"/>
        <geom size="0.0001" rgba="0 0 0.8 1"/>
        <body name="1_aftc_29_taxel_base_link">
          <inertial pos="0 0 0" mass="0.005" diaginertia="1e-06 1e-06 1e-06"/>
          <joint name="j_29_z" pos="0 0 0" axis="0 0 1" type="slide" range="-0.001 0" actuatorfrcrange="-100 100"/>
          <geom size="0.001" rgba="0 0 0.8 1"/>
        </body>
      </body>
    </body>
    <body name="1_aftc_30_base2x" pos="-0.0273 0.0038 0.01254" quat="0.707107 0 -0.707107 0">
      <inertial pos="0 0 0" mass="0.005" diaginertia="1e-06 1e-06 1e-06"/>
      <joint name="j_30_x" pos="0 0 0" axis="1 0 0" type="slide" range="-0.0015 0.0015" actuatorfrcrange="-100 100"/>
      <geom size="0.0001" rgba="0 0 0.8 1"/>
      <body name="1_aftc_30_x2y">
        <inertial pos="0 0 0" mass="0.005" diaginertia="1e-06 1e-06 1e-06"/>
        <joint name="j_30_y" pos="0 0 0" axis="0 1 0" type="slide" range="-0.0015 0.0015" actuatorfrcrange="-100 100"/>
        <geom size="0.0001" rgba="0 0 0.8 1"/>
        <body name="1_aftc_30_taxel_base_link">
          <inertial pos="0 0 0" mass="0.005" diaginertia="1e-06 1e-06 1e-06"/>
          <joint name="j_30_z" pos="0 0 0" axis="0 0 1" type="slide" range="-0.001 0" actuatorfrcrange="-100 100"/>
          <geom size="0.001" rgba="0 0 0.8 1"/>
        </body>
      </body>
    </body>
  </worldbody>
</mujoco>
