<?xml version="1.0" ?>
<robot name="xela_finger_generated">

  <link name="rf_mcp">
    <inertial>
      <origin xyz="0.0 0.0 0.0" rpy="0.0 0.0 0.0"/>
      <mass value="0.044"/>
      <inertia ixx="1.1499e-05" ixy="3.049e-06" ixz="1.21e-07" iyy="7.796e-06" iyz="1.12e-07" izz="1.4759e-05"/>
    </inertial>
    <visual>
      <origin xyz="0.008406902261174496 0.007766243859716995 0.014657354985032912" rpy="0.0 0.0 0.0"/>
      <geometry>
        <mesh filename="package://assets/mcp_joint.stl"/>
      </geometry>
      <material name="mcp_joint_material">
        <color rgba="0.866667 0.866667 0.0509804 1.0"/>
      </material>
    </visual>
    <collision>
      <origin xyz="0.008406902261174496 0.007766243859716995 0.014657354985032912" rpy="0.0 0.0 0.0"/>
      <geometry>
        <mesh filename="package://assets/mcp_joint.stl"/>
      </geometry>
    </collision>
  </link>

  <link name="rf_pip">
    <inertial>
      <origin xyz="0.0 0.0 0.0" rpy="0.0 0.0 0.0"/>
      <mass value="0.032"/>
      <inertia ixx="4.798e-06" ixy="1.2e-08" ixz="4e-09" iyy="2.862e-06" iyz="1.1e-08" izz="4.234e-06"/>
    </inertial>
    <visual>
      <origin xyz="0.009643363092271328 0.0003 0.0007840340104173765" rpy="-1.5708 -1.5708 0.0"/>
      <geometry>
        <mesh filename="package://assets/pip.stl"/>
      </geometry>
      <material name="pip_material">
        <color rgba="0.74902 0.74902 0.74902 1.0"/>
      </material>
    </visual>
    <collision>
      <origin xyz="0.009643363092271328 0.0003 0.0007840340104173765" rpy="-1.5708 -1.5708 0.0"/>
      <geometry>
        <mesh filename="package://assets/pip.stl"/>
      </geometry>
    </collision>
  </link>

  <link name="rf_dip">
    <inertial>
      <origin xyz="0.0 0.0 0.0" rpy="0.0 0.0 0.0"/>
      <mass value="0.037"/>
      <inertia ixx="5.542e-06" ixy="-6.07e-07" ixz="-1.7e-08" iyy="5.727e-06" iyz="-2.3e-08" izz="6.682e-06"/>
    </inertial>
    <visual>
      <origin xyz="0.021133352895225003 -0.00843211914670488 0.00978508816209524" rpy="-3.1416 0.0 0.0"/>
      <geometry>
        <mesh filename="package://assets/dip.stl"/>
      </geometry>
      <material name="dip_material">
        <color rgba="0.866667 0.866667 0.0509804 1.0"/>
      </material>
    </visual>
    <collision>
      <origin xyz="0.021133352895225003 -0.00843211914670488 0.00978508816209524" rpy="-3.1416 0.0 0.0"/>
      <geometry>
        <mesh filename="package://assets/dip.stl"/>
      </geometry>
    </collision>
  </link>

  <link name="rf_fingertip">
    <inertial>
      <origin xyz="0.0 0.0 0.0" rpy="0.0 0.0 0.0"/>
      <mass value="0.016"/>
      <inertia ixx="3.368e-06" ixy="1.15e-07" ixz="0.0" iyy="1.556e-06" iyz="0.0" izz="2.863e-06"/>
    </inertial>
    <visual>
      <origin xyz="0.013286424108533503 -0.006114238386541987 0.0145" rpy="3.1416 0.0 0.0"/>
      <geometry>
        <mesh filename="package://assets/fingertip.stl"/>
      </geometry>
      <material name="fingertip_material">
        <color rgba="0.866667 0.866667 0.0509804 1.0"/>
      </material>
    </visual>
    <collision>
      <origin xyz="0.013286424108533503 -0.006114238386541987 0.0145" rpy="3.1416 0.0 0.0"/>
      <geometry>
        <mesh filename="package://assets/fingertip.stl"/>
      </geometry>
    </collision>
  </link>

  <link name="rf_realtip">
    <inertial>
      <origin xyz="0.0 0.0 0.0" rpy="0.0 0.0 0.0"/>
      <mass value="0.1"/>
      <inertia ixx="2.5e-05" ixy="0.0" ixz="0.0" iyy="2.5e-05" iyz="0.0" izz="2.5e-05"/>
    </inertial>
    <visual>
      <origin xyz="0.0 0.0 0.0" rpy="0.0 0.0 0.0"/>
      <geometry>
        <sphere radius="0.005"/>
      </geometry>
      <material name="ball_material">
        <color rgba="1.0 0.0 0.0 1.0"/>
      </material>
    </visual>
    <collision>
      <origin xyz="0.0 0.0 0.0" rpy="0.0 0.0 0.0"/>
      <geometry>
        <sphere radius="0.005"/>
      </geometry>
    </collision>
  </link>

  <joint name="rf_rot" type="revolute">
    <origin xyz="-0.012200000000000008 0.038099999999999995 0.0145" rpy="-1.5707963267948966 0.0 1.5707963267948943"/>
    <parent link="rf_mcp"/>
    <child link="rf_pip"/>
    <axis xyz="0 0 -1"/>
    <limit effort="0.95" velocity="8.48" lower="-1.047" upper="1.047"/>
  </joint>

  <joint name="rf_pip" type="revolute">
    <origin xyz="0.014999999999999968 0.014299999999999905 -0.012999999999999824" rpy="1.571 -1.571 0"/>
    <parent link="rf_pip"/>
    <child link="rf_dip"/>
    <axis xyz="0 0 -1"/>
    <limit effort="0.95" velocity="8.48" lower="-0.506" upper="1.885"/>
  </joint>

  <joint name="rf_dip" type="revolute">
    <origin xyz="-4.088058249557269e-09 -0.03610000421036737 0.0002000000000000786" rpy="0.0 0.0 0.0"/>
    <parent link="rf_dip"/>
    <child link="rf_fingertip"/>
    <axis xyz="0 0 -1"/>
    <limit effort="0.95" velocity="8.48" lower="-0.366" upper="2.042"/>
  </joint>

  <joint name="rf_realtip" type="fixed">
    <origin xyz="0.02 -0.07 0.015" rpy="0.0 0.0 0.0"/>
    <parent link="rf_fingertip"/>
    <child link="rf_realtip"/>
    <axis xyz="0 0 -1"/>
    
  </joint>

<link name="base"/>
<joint name="base" type="fixed">
  <origin xyz="0 0 0.2" rpy="1.57 0 0"/>
  <parent link="base"/>
  <child link="rf_mcp"/>
</joint>
</robot>
