<?xml version="1.0" ?>
<!-- Generated using onshape-to-robot -->
<!-- Onshape https://cad.onshape.com/documents/8570a76a8c0c31c84724c6f7/w/c9d7fe5a7e1c98ade57ae24b/e/4616741f8203d341b4c11c90 -->
<mujoco model="leapXela_pointcloud">
  <compiler angle="radian" meshdir="assets" autolimits="true"/>
  <default>
    <default class="leapXela_pointcloud">
      <joint frictionloss="0.1" armature="0.005"/>
      <position kp="50" dampratio="1"/>
      <default class="visual">
        <geom type="mesh" contype="0" conaffinity="0" group="2"/>
      </default>
      <default class="collision">
        <geom group="3"/>
      </default>
    </default>
  </default>
  <worldbody>
    <!-- Link leap_hand_xela_back_cover -->
    <body name="leap_hand_xela_back_cover" pos="0 0 0" quat="1 0 0 0" childclass="leapXela_pointcloud">
      <freejoint name="leap_hand_xela_back_cover_freejoint"/>
      <inertial pos="-0.000780549 -0.00686016 0.0718797" mass="1.50836" fullinertia="0.00330843 0.00420899 0.00177685 6.79303e-05 -0.000176923 0.000182026"/>
      <!-- Part leap_hand_xela_motorholder -->
      <geom type="mesh" class="visual" pos="0.0180627 0.023 0.0834096" quat="0 0.707107 0 -0.707107" mesh="leap_hand_xela_motorholder" material="leap_hand_xela_motorholder_material"/>
      <geom type="mesh" class="collision" pos="0.0180627 0.023 0.0834096" quat="0 0.707107 0 -0.707107" mesh="leap_hand_xela_motorholder" material="leap_hand_xela_motorholder_material"/>
      <!-- Part uspa46 -->
      <geom type="mesh" class="visual" pos="-0.005515 -0.027 0.0631" quat="0 -0 -0 -1" mesh="uspa46" material="uspa46_material"/>
      <geom type="mesh" class="collision" pos="-0.005515 -0.027 0.0631" quat="0 -0 -0 -1" mesh="uspa46" material="uspa46_material"/>
      <!-- Part thp0_unified -->
      <geom type="mesh" class="visual" pos="0.0235627 -0.013 0.0845" quat="0.707107 -0 -0 0.707107" mesh="thp0_unified" material="thp0_unified_material"/>
      <geom type="mesh" class="collision" pos="0.0235627 -0.013 0.0845" quat="0.707107 -0 -0 0.707107" mesh="thp0_unified" material="thp0_unified_material"/>
      <!-- Part p5_unified -->
      <geom type="mesh" class="visual" pos="-0.03767 -0.009 0.1306" quat="0.5 0.5 -0.5 0.5" mesh="p5_unified" material="p5_unified_material"/>
      <geom type="mesh" class="collision" pos="-0.03767 -0.009 0.1306" quat="0.5 0.5 -0.5 0.5" mesh="p5_unified" material="p5_unified_material"/>
      <!-- Part top_palm -->
      <geom type="mesh" class="visual" pos="0.00785 -0.023 0.123706" quat="0 -0 1 -0" mesh="top_palm" material="top_palm_material"/>
      <geom type="mesh" class="collision" pos="0.00785 -0.023 0.123706" quat="0 -0 1 -0" mesh="top_palm" material="top_palm_material"/>
      <!-- Part p5_unified_2 -->
      <geom type="mesh" class="visual" pos="0.00778 -0.009 0.1306" quat="0.5 0.5 -0.5 0.5" mesh="p5_unified" material="p5_unified_material"/>
      <geom type="mesh" class="collision" pos="0.00778 -0.009 0.1306" quat="0.5 0.5 -0.5 0.5" mesh="p5_unified" material="p5_unified_material"/>
      <!-- Part uspa46_2 -->
      <geom type="mesh" class="visual" pos="-0.005515 -0.027 0.0962" quat="0 -0 -0 -1" mesh="uspa46" material="uspa46_material"/>
      <geom type="mesh" class="collision" pos="-0.005515 -0.027 0.0962" quat="0 -0 -0 -1" mesh="uspa46" material="uspa46_material"/>
      <!-- Part p5_unified_3 -->
      <geom type="mesh" class="visual" pos="0.05323 -0.009 0.1306" quat="0.5 0.5 -0.5 0.5" mesh="p5_unified" material="p5_unified_material"/>
      <geom type="mesh" class="collision" pos="0.05323 -0.009 0.1306" quat="0.5 0.5 -0.5 0.5" mesh="p5_unified" material="p5_unified_material"/>
      <!-- Part uspa46_3 -->
      <geom type="mesh" class="visual" pos="0.044015 -0.027 0.0962" quat="0 -1 0 0" mesh="uspa46" material="uspa46_material"/>
      <geom type="mesh" class="collision" pos="0.044015 -0.027 0.0962" quat="0 -1 0 0" mesh="uspa46" material="uspa46_material"/>
      <!-- Part leap_hand_xela_back_cover -->
      <geom type="mesh" class="visual" pos="-0.0293149 0.023 0.131221" quat="0.707107 -0 -0.707107 0" mesh="leap_hand_xela_back_cover" material="leap_hand_xela_back_cover_material"/>
      <geom type="mesh" class="collision" pos="-0.0293149 0.023 0.131221" quat="0.707107 -0 -0.707107 0" mesh="leap_hand_xela_back_cover" material="leap_hand_xela_back_cover_material"/>
      <!-- Part leap_hand_xela_side_cover -->
      <geom type="mesh" class="visual" pos="-0.0503368 0 0.110009" quat="0.707104 0.707104 0.00183435 -0.00183435" mesh="leap_hand_xela_side_cover" material="leap_hand_xela_side_cover_material"/>
      <geom type="mesh" class="collision" pos="-0.0503368 0 0.110009" quat="0.707104 0.707104 0.00183435 -0.00183435" mesh="leap_hand_xela_side_cover" material="leap_hand_xela_side_cover_material"/>
      <!-- Part leap_hand_xela_bottom -->
      <geom type="mesh" class="visual" pos="0 -0.023 0.0425" quat="0 0 -1 0" mesh="leap_hand_xela_bottom" material="leap_hand_xela_bottom_material"/>
      <geom type="mesh" class="collision" pos="0 -0.023 0.0425" quat="0 0 -1 0" mesh="leap_hand_xela_bottom" material="leap_hand_xela_bottom_material"/>
      <!-- Part palm_face -->
      <geom type="mesh" class="visual" pos="-0.0283776 -0.029 0.131221" quat="0.707107 -0 -0.707107 0" mesh="palm_face" material="palm_face_material"/>
      <geom type="mesh" class="collision" pos="-0.0283776 -0.029 0.131221" quat="0.707107 -0 -0.707107 0" mesh="palm_face" material="palm_face_material"/>
      <!-- Link p4_unified -->
      <body name="p4_unified" pos="-0.02317 -0.0165 0.1436" quat="0 0.707107 -0 0.707107">
        <!-- Joint from leap_hand_xela_back_cover to p4_unified -->
        <joint axis="0 0 1" name="rf_mcp" type="hinge" range="-0.3141592653589784 2.2340214425527427"/>
        <inertial pos="0.0342889 -0.0265621 -0.0145004" mass="0.0353104" fullinertia="6.90801e-06 1.04766e-05 1.10431e-05 2.26365e-06 1.79475e-07 -1.82708e-07"/>
        <!-- Part p4_unified -->
        <geom type="mesh" class="visual" pos="0.0048 -0 -0.0145" quat="0.5 0.5 0.5 -0.5" mesh="p4_unified" material="p4_unified_material"/>
        <geom type="mesh" class="collision" pos="0.0048 -0 -0.0145" quat="0.5 0.5 0.5 -0.5" mesh="p4_unified" material="p4_unified_material"/>
        <!-- Link p3_unified -->
        <body name="p3_unified" pos="0.0326 -0.0123 -0.0145" quat="0.5 -0.5 -0.5 -0.5">
          <!-- Joint from p4_unified to p3_unified -->
          <joint axis="0 0 1" name="rf_rot" type="hinge" range="-1.0471975511965976 1.0471975511965976"/>
          <inertial pos="-0.000258994 0.00848001 0.0133488" mass="0.0241611" fullinertia="3.54425e-06 2.67248e-06 3.5384e-06 -1.6457e-08 -1.5221e-08 -1.71388e-07"/>
          <!-- Part p3_unified -->
          <geom type="mesh" class="visual" pos="0 0.0075 -0" quat="0.5 -0.5 -0.5 -0.5" mesh="p3_unified" material="p3_unified_material"/>
          <geom type="mesh" class="collision" pos="0 0.0075 -0" quat="0.5 -0.5 -0.5 -0.5" mesh="p3_unified" material="p3_unified_material"/>
          <!-- Link p2_unified -->
          <body name="p2_unified" pos="0.0145 0.015 0.013" quat="0.5 0.5 0.5 0.5">
            <!-- Joint from p3_unified to p2_unified -->
            <joint axis="0 0 1" name="rf_pip" type="hinge" range="-0.506145483078337 1.8849555921538945"/>
            <inertial pos="0.0304899 -0.00688132 -0.0146269" mass="0.0355531" fullinertia="8.11059e-06 6.98155e-06 9.0141e-06 5.66349e-07 1.88699e-07 -9.6344e-08"/>
            <!-- Part p2_unified -->
            <geom type="mesh" class="visual" pos="0.00905 -0 -0.0145" quat="0.5 0.5 0.5 -0.5" mesh="p2_unified" material="p2_unified_material"/>
            <geom type="mesh" class="collision" pos="0.00905 -0 -0.0145" quat="0.5 0.5 0.5 -0.5" mesh="p2_unified" material="p2_unified_material"/>
            <!-- Link finger -->
            <body name="finger" pos="0.0361 -0 -0.0291" quat="0.707107 -0 0 0.707107">
              <!-- Joint from p2_unified to finger -->
              <joint axis="0 0 1" name="rf_dip" type="hinge"/>
              <inertial pos="-0.00529579 -0.0199202 0.0143731" mass="0.0635842" fullinertia="1.65611e-05 1.41439e-05 1.26495e-05 -2.61948e-06 -1.04904e-07 -1.52298e-07"/>
              <!-- Part fingertip_fix -->
              <geom type="mesh" class="visual" pos="-0.000739103 -0.025 0.0144961" quat="0.5 -0.5 -0.5 -0.5" mesh="fingertip_fix" material="fingertip_fix_material"/>
              <geom type="mesh" class="collision" pos="-0.000739103 -0.025 0.0144961" quat="0.5 -0.5 -0.5 -0.5" mesh="fingertip_fix" material="fingertip_fix_material"/>
              <!-- Part part_2 -->
              <geom type="mesh" class="visual" pos="-0 -0.03 0.0145" quat="0 0.707107 -0 0.707107" mesh="part_2" material="part_2_material"/>
              <geom type="mesh" class="collision" pos="-0 -0.03 0.0145" quat="0 0.707107 -0 0.707107" mesh="part_2" material="part_2_material"/>
              <!-- Part pointcloud -->
              <geom type="mesh" class="visual" pos="-0.0139201 -0.025 0.0145" quat="0.5 0.5 -0.5 0.5" mesh="pointcloud" material="pointcloud_material"/>
              <geom type="mesh" class="collision" pos="-0.0139201 -0.025 0.0145" quat="0.5 0.5 -0.5 0.5" mesh="pointcloud" material="pointcloud_material"/>
            </body>
          </body>
        </body>
      </body>
      <!-- Link p4_unified_2 -->
      <body name="p4_unified_2" pos="0.02228 -0.0165 0.1436" quat="0 0.707107 -0 0.707107">
        <!-- Joint from leap_hand_xela_back_cover to p4_unified_2 -->
        <joint axis="0 0 1" name="mf_mcp" type="hinge" range="-0.3141592653589793 2.234021442552742"/>
        <inertial pos="0.0342889 -0.0265621 -0.0145004" mass="0.0353104" fullinertia="6.90801e-06 1.04766e-05 1.10431e-05 2.26365e-06 1.79475e-07 -1.82708e-07"/>
        <!-- Part p4_unified_2 -->
        <geom type="mesh" class="visual" pos="0.0048 -0 -0.0145" quat="0.5 0.5 0.5 -0.5" mesh="p4_unified" material="p4_unified_material"/>
        <geom type="mesh" class="collision" pos="0.0048 -0 -0.0145" quat="0.5 0.5 0.5 -0.5" mesh="p4_unified" material="p4_unified_material"/>
        <!-- Link p3_unified_2 -->
        <body name="p3_unified_2" pos="0.0326 -0.0123 -0.0145" quat="0.5 -0.5 -0.5 -0.5">
          <!-- Joint from p4_unified_2 to p3_unified_2 -->
          <joint axis="0 0 1" name="mf_rot" type="hinge" range="-1.0471975511965976 1.0471975511965976"/>
          <inertial pos="-0.000258994 0.00848001 0.0133488" mass="0.0241611" fullinertia="3.54425e-06 2.67248e-06 3.5384e-06 -1.6457e-08 -1.5221e-08 -1.71388e-07"/>
          <!-- Part p3_unified_2 -->
          <geom type="mesh" class="visual" pos="-0 0.0075 -0" quat="0.5 -0.5 -0.5 -0.5" mesh="p3_unified" material="p3_unified_material"/>
          <geom type="mesh" class="collision" pos="-0 0.0075 -0" quat="0.5 -0.5 -0.5 -0.5" mesh="p3_unified" material="p3_unified_material"/>
          <!-- Link p2_unified_2 -->
          <body name="p2_unified_2" pos="0.0145 0.015 0.013" quat="0.5 0.5 0.5 0.5">
            <!-- Joint from p3_unified_2 to p2_unified_2 -->
            <joint axis="0 0 1" name="mf_pip" type="hinge" range="-0.506145483078337 1.8849555921538945"/>
            <inertial pos="0.0304899 -0.00688132 -0.0146269" mass="0.0355531" fullinertia="8.11059e-06 6.98155e-06 9.0141e-06 5.66349e-07 1.88699e-07 -9.6344e-08"/>
            <!-- Part p2_unified_2 -->
            <geom type="mesh" class="visual" pos="0.00905 -0 -0.0145" quat="0.5 0.5 0.5 -0.5" mesh="p2_unified" material="p2_unified_material"/>
            <geom type="mesh" class="collision" pos="0.00905 -0 -0.0145" quat="0.5 0.5 0.5 -0.5" mesh="p2_unified" material="p2_unified_material"/>
            <!-- Link finger_2 -->
            <body name="finger_2" pos="0.0361 -0 -0.0291" quat="0.707107 -0 0 0.707107">
              <!-- Joint from p2_unified_2 to finger_2 -->
              <joint axis="0 0 1" name="mf_dip" type="hinge"/>
              <inertial pos="-0.00529579 -0.0199202 0.0143731" mass="0.0635842" fullinertia="1.65611e-05 1.41439e-05 1.26495e-05 -2.61948e-06 -1.04904e-07 -1.52298e-07"/>
              <!-- Part fingertip_fix_2 -->
              <geom type="mesh" class="visual" pos="-0.000739103 -0.025 0.0144961" quat="0.5 -0.5 -0.5 -0.5" mesh="fingertip_fix" material="fingertip_fix_material"/>
              <geom type="mesh" class="collision" pos="-0.000739103 -0.025 0.0144961" quat="0.5 -0.5 -0.5 -0.5" mesh="fingertip_fix" material="fingertip_fix_material"/>
              <!-- Part part_2_2 -->
              <geom type="mesh" class="visual" pos="-0 -0.03 0.0145" quat="0 0.707107 -0 0.707107" mesh="part_2" material="part_2_material"/>
              <geom type="mesh" class="collision" pos="-0 -0.03 0.0145" quat="0 0.707107 -0 0.707107" mesh="part_2" material="part_2_material"/>
              <!-- Part pointcloud_2 -->
              <geom type="mesh" class="visual" pos="-0.0139201 -0.025 0.0145" quat="0.5 0.5 -0.5 0.5" mesh="pointcloud" material="pointcloud_material"/>
              <geom type="mesh" class="collision" pos="-0.0139201 -0.025 0.0145" quat="0.5 0.5 -0.5 0.5" mesh="pointcloud" material="pointcloud_material"/>
            </body>
          </body>
        </body>
      </body>
      <!-- Link p4_unified_3 -->
      <body name="p4_unified_3" pos="0.06773 -0.0165 0.1436" quat="0 0.707107 -0 0.707107">
        <!-- Joint from leap_hand_xela_back_cover to p4_unified_3 -->
        <joint axis="0 0 1" name="if_mcp" type="hinge" range="-0.3141592653589793 2.234021442552742"/>
        <inertial pos="0.0342889 -0.0265621 -0.0145004" mass="0.0353104" fullinertia="6.90801e-06 1.04766e-05 1.10431e-05 2.26365e-06 1.79475e-07 -1.82708e-07"/>
        <!-- Part p4_unified_3 -->
        <geom type="mesh" class="visual" pos="0.0048 -0 -0.0145" quat="0.5 0.5 0.5 -0.5" mesh="p4_unified" material="p4_unified_material"/>
        <geom type="mesh" class="collision" pos="0.0048 -0 -0.0145" quat="0.5 0.5 0.5 -0.5" mesh="p4_unified" material="p4_unified_material"/>
        <!-- Link p3_unified_3 -->
        <body name="p3_unified_3" pos="0.0326 -0.0123 -0.0145" quat="0.5 -0.5 -0.5 -0.5">
          <!-- Joint from p4_unified_3 to p3_unified_3 -->
          <joint axis="0 0 1" name="if_rot" type="hinge" range="-1.0471975511965976 1.0471975511965976"/>
          <inertial pos="-0.000258994 0.00848001 0.0133488" mass="0.0241611" fullinertia="3.54425e-06 2.67248e-06 3.5384e-06 -1.6457e-08 -1.5221e-08 -1.71388e-07"/>
          <!-- Part p3_unified_3 -->
          <geom type="mesh" class="visual" pos="0 0.0075 -0" quat="0.5 -0.5 -0.5 -0.5" mesh="p3_unified" material="p3_unified_material"/>
          <geom type="mesh" class="collision" pos="0 0.0075 -0" quat="0.5 -0.5 -0.5 -0.5" mesh="p3_unified" material="p3_unified_material"/>
          <!-- Link p2_unified_3 -->
          <body name="p2_unified_3" pos="0.0145 0.015 0.013" quat="0.5 0.5 0.5 0.5">
            <!-- Joint from p3_unified_3 to p2_unified_3 -->
            <joint axis="0 0 1" name="if_pip" type="hinge" range="-0.506145483078337 1.8849555921538945"/>
            <inertial pos="0.0304899 -0.00688132 -0.0146269" mass="0.0355531" fullinertia="8.11059e-06 6.98155e-06 9.0141e-06 5.66349e-07 1.88699e-07 -9.6344e-08"/>
            <!-- Part p2_unified_3 -->
            <geom type="mesh" class="visual" pos="0.00905 -0 -0.0145" quat="0.5 0.5 0.5 -0.5" mesh="p2_unified" material="p2_unified_material"/>
            <geom type="mesh" class="collision" pos="0.00905 -0 -0.0145" quat="0.5 0.5 0.5 -0.5" mesh="p2_unified" material="p2_unified_material"/>
            <!-- Link finger_3 -->
            <body name="finger_3" pos="0.0361 -0 -0.0291" quat="0.707107 -0 0 0.707107">
              <!-- Joint from p2_unified_3 to finger_3 -->
              <joint axis="0 0 1" name="if_dip" type="hinge"/>
              <inertial pos="-0.00529579 -0.0199202 0.0143731" mass="0.0635842" fullinertia="1.65611e-05 1.41439e-05 1.26495e-05 -2.61948e-06 -1.04904e-07 -1.52298e-07"/>
              <!-- Part fingertip_fix_3 -->
              <geom type="mesh" class="visual" pos="-0.000739103 -0.025 0.0144961" quat="0.5 -0.5 -0.5 -0.5" mesh="fingertip_fix" material="fingertip_fix_material"/>
              <geom type="mesh" class="collision" pos="-0.000739103 -0.025 0.0144961" quat="0.5 -0.5 -0.5 -0.5" mesh="fingertip_fix" material="fingertip_fix_material"/>
              <!-- Part part_2_3 -->
              <geom type="mesh" class="visual" pos="-0 -0.03 0.0145" quat="0 0.707107 -0 0.707107" mesh="part_2" material="part_2_material"/>
              <geom type="mesh" class="collision" pos="-0 -0.03 0.0145" quat="0 0.707107 -0 0.707107" mesh="part_2" material="part_2_material"/>
              <!-- Part pointcloud_3 -->
              <geom type="mesh" class="visual" pos="-0.0139201 -0.025 0.0145" quat="0.5 0.5 -0.5 0.5" mesh="pointcloud" material="pointcloud_material"/>
              <geom type="mesh" class="collision" pos="-0.0139201 -0.025 0.0145" quat="0.5 0.5 -0.5 0.5" mesh="pointcloud" material="pointcloud_material"/>
            </body>
          </body>
        </body>
      </body>
      <!-- Link thp2_unified -->
      <body name="thp2_unified" pos="0.0480627 -0.013 0.07" quat="0 0 1 -0">
        <!-- Joint from leap_hand_xela_back_cover to thp2_unified -->
        <joint axis="0 0 1" name="th_cmc" type="hinge" range="-0.3490658503988659 2.0943951023931953"/>
        <inertial pos="-0.000232587 0.00882444 0.0117326" mass="0.0247742" fullinertia="3.63585e-06 2.65288e-06 4.33226e-06 2.0599e-08 8.412e-09 -1.4817e-08"/>
        <!-- Part thp2_unified -->
        <geom type="mesh" class="visual" pos="0 0.0075 0" quat="0.5 -0.5 -0.5 -0.5" mesh="thp2_unified" material="thp2_unified_material"/>
        <geom type="mesh" class="collision" pos="0 0.0075 0" quat="0.5 -0.5 -0.5 -0.5" mesh="thp2_unified" material="thp2_unified_material"/>
        <!-- Link clipper -->
        <body name="clipper" pos="-0.0144 -0 0.013" quat="0.5 -0.5 -0.5 0.5">
          <!-- Joint from thp2_unified to clipper -->
          <joint axis="0 0 1" name="th_axl" type="hinge" range="-0.3490658503988659 2.0943951023931953"/>
          <inertial pos="0.000911557 -0.00108086 0.00811114" mass="0.00468118" fullinertia="4.40805e-07 1.184e-06 1.12942e-06 -4.612e-09 -4.6465e-08 4.476e-09"/>
          <!-- Part thconnector -->
          <geom type="mesh" class="visual" pos="-0.0173 0 0.019" quat="0.707107 0.707107 0 0" mesh="thconnector" material="thconnector_material"/>
          <geom type="mesh" class="collision" pos="-0.0173 0 0.019" quat="0.707107 0.707107 0 0" mesh="thconnector" material="thconnector_material"/>
          <!-- Part clipper -->
          <geom type="mesh" class="visual" pos="0.0155 -0.006 0.019" quat="0 -0.707107 -0.707107 0" mesh="clipper" material="clipper_material"/>
          <geom type="mesh" class="collision" pos="0.0155 -0.006 0.019" quat="0 -0.707107 -0.707107 0" mesh="clipper" material="clipper_material"/>
          <!-- Link thp1_unified -->
          <body name="thp1_unified" pos="0.0145 -0 0.019" quat="0.5 0.5 -0.5 -0.5">
            <!-- Joint from clipper to thp1_unified -->
            <joint axis="0 0 1" name="th_mcp" type="hinge" range="-0.47123889803846897 2.443460952792061"/>
            <inertial pos="0.00144426 0.0112332 0.0144179" mass="0.0325393" fullinertia="7.98976e-06 4.90108e-06 7.77953e-06 8.1084e-08 -9.5788e-08 1.43138e-07"/>
            <!-- Part thp1_unified -->
            <geom type="mesh" class="visual" pos="-0 0.0245 0.0145" quat="1 0 0 0" mesh="thp1_unified" material="thp1_unified_material"/>
            <geom type="mesh" class="collision" pos="-0 0.0245 0.0145" quat="1 0 0 0" mesh="thp1_unified" material="thp1_unified_material"/>
            <!-- Link thumb -->
            <body name="thumb" pos="-0 0.0446 0" quat="0 0 0 -1">
              <!-- Joint from thp1_unified to thumb -->
              <joint axis="0 0 1" name="th_ipl" type="hinge"/>
              <inertial pos="-0.0117549 -0.0183374 0.0150425" mass="0.0815862" fullinertia="2.39909e-05 1.17597e-05 2.24416e-05 1.95138e-06 1.96643e-07 -6.68473e-07"/>
              <!-- Part servo_unified -->
              <geom type="mesh" class="visual" pos="0 0 0.0065" quat="0 0 1 0" mesh="servo_unified" material="servo_unified_material"/>
              <geom type="mesh" class="collision" pos="0 0 0.0065" quat="0 0 1 0" mesh="servo_unified" material="servo_unified_material"/>
              <!-- Part part10 -->
              <geom type="mesh" class="visual" pos="-0 -0.0275 0.014504" quat="0.707107 0.707107 0 -0" mesh="part10" material="part10_material"/>
              <geom type="mesh" class="collision" pos="-0 -0.0275 0.014504" quat="0.707107 0.707107 0 -0" mesh="part10" material="part10_material"/>
              <!-- Part part_2_4 -->
              <geom type="mesh" class="visual" pos="0 -0.0350003 0.014504" quat="0 -0.707107 0 -0.707107" mesh="part_2" material="part_2_material"/>
              <geom type="mesh" class="collision" pos="0 -0.0350003 0.014504" quat="0 -0.707107 0 -0.707107" mesh="part_2" material="part_2_material"/>
              <!-- Part pointcloud_4 -->
              <geom type="mesh" class="visual" pos="-0.0139201 -0.0300003 0.014504" quat="0.5 0.5 -0.5 0.5" mesh="pointcloud" material="pointcloud_material"/>
              <geom type="mesh" class="collision" pos="-0.0139201 -0.0300003 0.014504" quat="0.5 0.5 -0.5 0.5" mesh="pointcloud" material="pointcloud_material"/>
            </body>
          </body>
        </body>
      </body>
    </body>
  </worldbody>
  <asset>
    <mesh file="clipper.stl"/>
    <mesh file="leap_hand_xela_bottom.stl"/>
    <mesh file="thconnector.stl"/>
    <mesh file="p4_unified.stl"/>
    <mesh file="fingertip_fix.stl"/>
    <mesh file="uspa46.stl"/>
    <mesh file="p2_unified.stl"/>
    <mesh file="servo_unified.stl"/>
    <mesh file="thp2_unified.stl"/>
    <mesh file="part_2.stl"/>
    <mesh file="part10.stl"/>
    <mesh file="thp0_unified.stl"/>
    <mesh file="palm_face.stl"/>
    <mesh file="leap_hand_xela_motorholder.stl"/>
    <mesh file="pointcloud.stl"/>
    <mesh file="thp1_unified.stl"/>
    <mesh file="top_palm.stl"/>
    <mesh file="p3_unified.stl"/>
    <mesh file="p5_unified.stl"/>
    <mesh file="leap_hand_xela_side_cover.stl"/>
    <mesh file="leap_hand_xela_back_cover.stl"/>
    <material name="leap_hand_xela_motorholder_material" rgba="0.792157 0.819608 0.933333 1"/>
    <material name="uspa46_material" rgba="0.792157 0.819608 0.933333 1"/>
    <material name="thp0_unified_material" rgba="0.498039 0.498039 0.498039 1"/>
    <material name="p5_unified_material" rgba="0.980392 0.713725 0.00392157 1"/>
    <material name="top_palm_material" rgba="0.792157 0.819608 0.933333 1"/>
    <material name="leap_hand_xela_back_cover_material" rgba="0.792157 0.819608 0.933333 1"/>
    <material name="leap_hand_xela_side_cover_material" rgba="0.792157 0.819608 0.933333 1"/>
    <material name="leap_hand_xela_bottom_material" rgba="0.792157 0.819608 0.933333 1"/>
    <material name="palm_face_material" rgba="0.792157 0.819608 0.933333 1"/>
    <material name="p4_unified_material" rgba="0.972549 0.529412 0.00392157 1"/>
    <material name="p3_unified_material" rgba="0.972549 0.529412 0.00392157 1"/>
    <material name="p2_unified_material" rgba="0.768627 0.886275 0.952941 1"/>
    <material name="fingertip_fix_material" rgba="0.792157 0.819608 0.933333 1"/>
    <material name="part_2_material" rgba="0.647059 0.647059 0.647059 1"/>
    <material name="pointcloud_material" rgba="0.615686 0.811765 0.929412 1"/>
    <material name="thp2_unified_material" rgba="0.980392 0.713725 0.00392157 1"/>
    <material name="thconnector_material" rgba="0.792157 0.819608 0.933333 1"/>
    <material name="clipper_material" rgba="0.792157 0.819608 0.933333 1"/>
    <material name="thp1_unified_material" rgba="0.647059 0.647059 0.647059 1"/>
    <material name="servo_unified_material" rgba="0.498039 0.498039 0.498039 1"/>
    <material name="part10_material" rgba="0.792157 0.819608 0.933333 1"/>
  </asset>
  <actuator>
    <position class="leapXela_pointcloud" name="rf_mcp" joint="rf_mcp" inheritrange="1"/>
    <position class="leapXela_pointcloud" name="rf_rot" joint="rf_rot" inheritrange="1"/>
    <position class="leapXela_pointcloud" name="rf_pip" joint="rf_pip" inheritrange="1"/>
    <position class="leapXela_pointcloud" name="rf_dip" joint="rf_dip"/>
    <position class="leapXela_pointcloud" name="mf_mcp" joint="mf_mcp" inheritrange="1"/>
    <position class="leapXela_pointcloud" name="mf_rot" joint="mf_rot" inheritrange="1"/>
    <position class="leapXela_pointcloud" name="mf_pip" joint="mf_pip" inheritrange="1"/>
    <position class="leapXela_pointcloud" name="mf_dip" joint="mf_dip"/>
    <position class="leapXela_pointcloud" name="if_mcp" joint="if_mcp" inheritrange="1"/>
    <position class="leapXela_pointcloud" name="if_rot" joint="if_rot" inheritrange="1"/>
    <position class="leapXela_pointcloud" name="if_pip" joint="if_pip" inheritrange="1"/>
    <position class="leapXela_pointcloud" name="if_dip" joint="if_dip"/>
    <position class="leapXela_pointcloud" name="th_cmc" joint="th_cmc" inheritrange="1"/>
    <position class="leapXela_pointcloud" name="th_axl" joint="th_axl" inheritrange="1"/>
    <position class="leapXela_pointcloud" name="th_mcp" joint="th_mcp" inheritrange="1"/>
    <position class="leapXela_pointcloud" name="th_ipl" joint="th_ipl"/>
  </actuator>
  <equality/>
</mujoco>
